Workbook

Sheet Campaign Settings
A1: Campaign Settings:
A3: Location Targeting | B3: Sandton, Gauteng, South Africa
A4: Location Exclusions | B4: N/a
A10: Campaign Level Negatives - | B10: See Keywords
A12: Call Extensions
A13: Location Extensions
A15: Scheduling | B15: 24/7
A17: Budget | B17: =5*25 -> 125

Sheet Ad Groups
B2: Campaign | C2: Ad Groups | F2: Total Ad Groups | G2: =COUNTA(C3:C1048576) -> 6
B3: Campaign 1 | C3: Emergency Plumbing
C4: Residential Plumbing
C5: Commercial Plumbing
C6: Leak Detection
C7: Drain Cleaning
C8: Geyser Replacement & Repairs

Sheet Keywords
B2: ='Ad Groups'!C3 -> Emergency Plumbing | C2: =IF('Ad Groups'!C4=0," ",'Ad Groups'!C4) -> Residential Plumbing | D2: =IF('Ad Groups'!C5=0," ",'Ad Groups'!C5) -> Commercial Plumbing | E2: =IF('Ad Groups'!C6=0," ",'Ad Groups'!C6) -> Leak Detection | F2: =IF('Ad Groups'!C7=0," ",'Ad Groups'!C7) -> Drain Cleaning | G2: =IF('Ad Groups'!C8=0," ",'Ad Groups'!C8) -> Geyser Replacement & Repairs | H2: =IF('Ad Groups'!C9=0," ",'Ad Groups'!C9) | I2: =IF('Ad Groups'!C10=0," ",'Ad Groups'!C10) | J2: =IF('Campaign Settings'!B1=0," ",'Campaign Settings'!B1) | K2: =IF('Campaign Settings'!B2=0," ",'Campaign Settings'!B2) | R2: =IF('Campaign Settings'!B9=0," ",'Campaign Settings'!B9) | S2: =IF('Campaign Settings'!B10=0," ",'Campaign Settings'!B10) -> See Keywords | T2: =IF('Ad Groups'!C21=0," ",'Ad Groups'!C21) | U2: =IF('Ad Groups'!C22=0," ",'Ad Groups'!C22) | V2: =IF('Ad Groups'!C23=0," ",'Ad Groups'!C23) | W2: =IF('Ad Groups'!C24=0," ",'Ad Groups'!C24) | X2: =IF('Ad Groups'!C25=0," ",'Ad Groups'!C25) | Y2: =IF('Ad Groups'!C26=0," ",'Ad Groups'!C26) | Z2: =IF('Ad Groups'!C27=0," ",'Ad Groups'!C27) | AA2: =IF('Ad Groups'!C28=0," ",'Ad Groups'!C28) | AB2: =IF('Ad Groups'!C29=0," ",'Ad Groups'!C29) | AC2: =IF('Ad Groups'!C30=0," ",'Ad Groups'!C30) | AD2: =IF('Ad Groups'!C31=0," ",'Ad Groups'!C31) | AE2: =IF('Ad Groups'!C32=0," ",'Ad Groups'!C32) | AF2: =IF('Ad Groups'!C33=0," ",'Ad Groups'!C33) | AG2: =IF('Ad Groups'!C34=0," ",'Ad Groups'!C34) | AH2: =IF('Ad Groups'!C35=0," ",'Ad Groups'!C35) | AI2: =IF('Ad Groups'!C36=0," ",'Ad Groups'!C36) | AJ2: =IF('Ad Groups'!C37=0," ",'Ad Groups'!C37) | AK2: =IF('Ad Groups'!C38=0," ",'Ad Groups'!C38) | AL2: =IF('Ad Groups'!C39=0," ",'Ad Groups'!C39) | AM2: =IF('Ad Groups'!C40=0," ",'Ad Groups'!C40) | AN2: =IF('Ad Groups'!C41=0," ",'Ad Groups'!C41) | AO2: =IF('Ad Groups'!C42=0," ",'Ad Groups'!C42) | AP2: =IF('Ad Groups'!C43=0," ",'Ad Groups'!C43) | AQ2: =IF('Ad Groups'!C44=0," ",'Ad Groups'!C44) | AR2: =IF('Ad Groups'!C45=0," ",'Ad Groups'!C45) | AS2: =IF('Ad Groups'!C46=0," ",'Ad Groups'!C46) | AT2: =IF('Ad Groups'!C47=0," ",'Ad Groups'!C47) | AU2: =IF('Ad Groups'!C48=0," ",'Ad Groups'!C48) | AV2: =IF('Ad Groups'!C49=0," ",'Ad Groups'!C49) | AW2: =IF('Ad Groups'!C50=0," ",'Ad Groups'!C50) | AX2: =IF('Ad Groups'!C51=0," ",'Ad Groups'!C51) | AY2: =IF('Ad Groups'!C52=0," ",'Ad Groups'!C52) | AZ2: =IF('Ad Groups'!C53=0," ",'Ad Groups'!C53) | BA2: =IF('Ad Groups'!C54=0," ",'Ad Groups'!C54) | BB2: =IF('Ad Groups'!C55=0," ",'Ad Groups'!C55) | BC2: =IF('Ad Groups'!C56=0," ",'Ad Groups'!C56) | BD2: =IF('Ad Groups'!C57=0," ",'Ad Groups'!C57) | BE2: =IF('Ad Groups'!C58=0," ",'Ad Groups'!C58) | BF2: =IF('Ad Groups'!C59=0," ",'Ad Groups'!C59) | BG2: =IF('Ad Groups'!C60=0," ",'Ad Groups'!C60)
B3: "Emergency Plumber Near Me" | C3: "Residential Plumbers" | D3: "Commercial Plumbing Contractors" | E3: "Water Leak Detection Service" | F3: "Blocked Drain Plumber" | G3: "Geyser Repair Johannesburg"
B4: "24 Hour Plumber Johannesburg" | C4: "Local Plumber For Home" | D4: "Office Building Plumber" | E4: "Find Hidden Water Leak" | F4: "Drain Cleaning Services" | G4: "Burst Geyser Replacement"
B5: "Emergency Plumbing Services" | C5: "Household Plumbing Repairs" | D5: "Commercial Maintenance Plumbing" | E5: "Leak Detection Company" | F5: "Unblock Sewer Line" | G5: "Solar Geyser Installers"
B6: "Burst Pipe Emergency Plumber" | C6: "Toilet Repair Plumber" | D6: "Industrial Plumbing Services" | E6: "Underground Leak Detection" | F6: "Clogged Drain Repair" | G6: "No Hot Water Plumber"
B7: [Emergency Plumber Near Me] | C7: [Residential Plumbers] | D7: [Commercial Plumbing Contractors] | E7: [Water Leak Detection Service] | F7: [Blocked Drain Plumber] | G7: [Geyser Repair Johannesburg]
B8: [24 Hour Plumber Johannesburg] | C8: [Local Plumber For Home] | D8: [Office Building Plumber] | E8: [Find Hidden Water Leak] | F8: [Drain Cleaning Services] | G8: [Burst Geyser Replacement]
B9: [Emergency Plumbing Services] | C9: [Household Plumbing Repairs] | D9: [Commercial Maintenance Plumbing] | E9: [Leak Detection Company] | F9: [Unblock Sewer Line] | G9: [Solar Geyser Installers]
B10: [Burst Pipe Emergency Plumber] | C10: [Toilet Repair Plumber] | D10: [Industrial Plumbing Services] | E10: [Underground Leak Detection] | F10: [Clogged Drain Repair] | G10: [No Hot Water Plumber]

Sheet Negative Keywords
B2: Campaign Negative | C2: =Keywords!B2 -> Emergency Plumbing | D2: =Keywords!C2 -> Residential Plumbing | E2: =Keywords!D2 -> Commercial Plumbing | F2: =Keywords!E2 -> Leak Detection | G2: =Keywords!F2 -> Drain Cleaning | H2: =Keywords!G2 -> Geyser Replacement & Repairs | I2: =IF('Ad Groups'!C9=0," ",'Ad Groups'!C9) | J2: =IF('Ad Groups'!C10=0," ",'Ad Groups'!C10) | K2: =IF('Campaign Settings'!B1=0," ",'Campaign Settings'!B1) | L2: =IF('Campaign Settings'!B2=0," ",'Campaign Settings'!B2) | S2: =IF('Campaign Settings'!B9=0," ",'Campaign Settings'!B9) | T2: =IF('Campaign Settings'!B10=0," ",'Campaign Settings'!B10) -> See Keywords | U2: =IF('Ad Groups'!C21=0," ",'Ad Groups'!C21) | V2: =IF('Ad Groups'!C22=0," ",'Ad Groups'!C22) | W2: =IF('Ad Groups'!C23=0," ",'Ad Groups'!C23) | X2: =IF('Ad Groups'!C24=0," ",'Ad Groups'!C24) | Y2: =IF('Ad Groups'!C25=0," ",'Ad Groups'!C25) | Z2: =IF('Ad Groups'!C26=0," ",'Ad Groups'!C26) | AA2: =IF('Ad Groups'!C27=0," ",'Ad Groups'!C27) | AB2: =IF('Ad Groups'!C28=0," ",'Ad Groups'!C28) | AC2: =IF('Ad Groups'!C29=0," ",'Ad Groups'!C29) | AD2: =IF('Ad Groups'!C30=0," ",'Ad Groups'!C30) | AE2: =IF('Ad Groups'!C31=0," ",'Ad Groups'!C31) | AF2: =IF('Ad Groups'!C32=0," ",'Ad Groups'!C32) | AG2: =IF('Ad Groups'!C33=0," ",'Ad Groups'!C33) | AH2: =IF('Ad Groups'!C34=0," ",'Ad Groups'!C34) | AI2: =IF('Ad Groups'!C35=0," ",'Ad Groups'!C35) | AJ2: =IF('Ad Groups'!C36=0," ",'Ad Groups'!C36) | AK2: =IF('Ad Groups'!C37=0," ",'Ad Groups'!C37) | AL2: =IF('Ad Groups'!C38=0," ",'Ad Groups'!C38) | AM2: =IF('Ad Groups'!C39=0," ",'Ad Groups'!C39) | AN2: =IF('Ad Groups'!C40=0," ",'Ad Groups'!C40) | AO2: =IF('Ad Groups'!C41=0," ",'Ad Groups'!C41) | AP2: =IF('Ad Groups'!C42=0," ",'Ad Groups'!C42) | AQ2: =IF('Ad Groups'!C43=0," ",'Ad Groups'!C43) | AR2: =IF('Ad Groups'!C44=0," ",'Ad Groups'!C44) | AS2: =IF('Ad Groups'!C45=0," ",'Ad Groups'!C45) | AT2: =IF('Ad Groups'!C46=0," ",'Ad Groups'!C46) | AU2: =IF('Ad Groups'!C47=0," ",'Ad Groups'!C47) | AV2: =IF('Ad Groups'!C48=0," ",'Ad Groups'!C48) | AW2: =IF('Ad Groups'!C49=0," ",'Ad Groups'!C49) | AX2: =IF('Ad Groups'!C50=0," ",'Ad Groups'!C50) | AY2: =IF('Ad Groups'!C51=0," ",'Ad Groups'!C51) | AZ2: =IF('Ad Groups'!C52=0," ",'Ad Groups'!C52) | BA2: =IF('Ad Groups'!C53=0," ",'Ad Groups'!C53) | BB2: =IF('Ad Groups'!C54=0," ",'Ad Groups'!C54) | BC2: =IF('Ad Groups'!C55=0," ",'Ad Groups'!C55) | BD2: =IF('Ad Groups'!C56=0," ",'Ad Groups'!C56) | BE2: =IF('Ad Groups'!C57=0," ",'Ad Groups'!C57) | BF2: =IF('Ad Groups'!C58=0," ",'Ad Groups'!C58) | BG2: =IF('Ad Groups'!C59=0," ",'Ad Groups'!C59) | BH2: =IF('Ad Groups'!C60=0," ",'Ad Groups'!C60)
C3: "Residential Plumbers" | D3: "Emergency Plumber Near Me" | E3: "Emergency Plumber Near Me" | F3: "Emergency Plumber Near Me" | G3: "Emergency Plumber Near Me" | H3: "Emergency Plumber Near Me"
B4: advice | C4: "Local Plumber For Home" | D4: "24 Hour Plumber Johannesburg" | E4: "24 Hour Plumber Johannesburg" | F4: "24 Hour Plumber Johannesburg" | G4: "24 Hour Plumber Johannesburg" | H4: "24 Hour Plumber Johannesburg"
B5: blog | C5: "Household Plumbing Repairs" | D5: "Emergency Plumbing Services" | E5: "Emergency Plumbing Services" | F5: "Emergency Plumbing Services" | G5: "Emergency Plumbing Services" | H5: "Emergency Plumbing Services"
B6: careers | C6: "Toilet Repair Plumber" | D6: "Burst Pipe Emergency Plumber" | E6: "Burst Pipe Emergency Plumber" | F6: "Burst Pipe Emergency Plumber" | G6: "Burst Pipe Emergency Plumber" | H6: "Burst Pipe Emergency Plumber"
B7: degree | C7: [Residential Plumbers] | D7: [Emergency Plumber Near Me] | E7: [Emergency Plumber Near Me] | F7: [Emergency Plumber Near Me] | G7: [Emergency Plumber Near Me] | H7: [Emergency Plumber Near Me]
B8: free | C8: [Local Plumber For Home] | D8: [24 Hour Plumber Johannesburg] | E8: [24 Hour Plumber Johannesburg] | F8: [24 Hour Plumber Johannesburg] | G8: [24 Hour Plumber Johannesburg] | H8: [24 Hour Plumber Johannesburg]
B9: how to | C9: [Household Plumbing Repairs] | D9: [Emergency Plumbing Services] | E9: [Emergency Plumbing Services] | F9: [Emergency Plumbing Services] | G9: [Emergency Plumbing Services] | H9: [Emergency Plumbing Services]
B10: ideas | C10: [Toilet Repair Plumber] | D10: [Burst Pipe Emergency Plumber] | E10: [Burst Pipe Emergency Plumber] | F10: [Burst Pipe Emergency Plumber] | G10: [Burst Pipe Emergency Plumber] | H10: [Burst Pipe Emergency Plumber]
B11: jobs | C11: "Commercial Plumbing Contractors" | D11: "Commercial Plumbing Contractors" | E11: "Residential Plumbers" | F11: "Residential Plumbers" | G11: "Residential Plumbers" | H11: "Residential Plumbers"
B12: login | C12: "Office Building Plumber" | D12: "Office Building Plumber" | E12: "Local Plumber For Home" | F12: "Local Plumber For Home" | G12: "Local Plumber For Home" | H12: "Local Plumber For Home"
B13: news | C13: "Commercial Maintenance Plumbing" | D13: "Commercial Maintenance Plumbing" | E13: "Household Plumbing Repairs" | F13: "Household Plumbing Repairs" | G13: "Household Plumbing Repairs" | H13: "Household Plumbing Repairs"
B14: pay | C14: "Industrial Plumbing Services" | D14: "Industrial Plumbing Services" | E14: "Toilet Repair Plumber" | F14: "Toilet Repair Plumber" | G14: "Toilet Repair Plumber" | H14: "Toilet Repair Plumber"
B15: plan | C15: [Commercial Plumbing Contractors] | D15: [Commercial Plumbing Contractors] | E15: [Residential Plumbers] | F15: [Residential Plumbers] | G15: [Residential Plumbers] | H15: [Residential Plumbers]
... B31: help | C31: [Blocked Drain Plumber] | D31: [Blocked Drain Plumber] | E31: [Blocked Drain Plumber] | F31: [Blocked Drain Plumber] | G31: [Water Leak Detection Service] | H31: [Water Leak Detection Service]
C32: [Drain Cleaning Services] | D32: [Drain Cleaning Services] | E32: [Drain Cleaning Services] | F32: [Drain Cleaning Services] | G32: [Find Hidden Water Leak] | H32: [Find Hidden Water Leak]
C33: [Unblock Sewer Line] | D33: [Unblock Sewer Line] | E33: [Unblock Sewer Line] | F33: [Unblock Sewer Line] | G33: [Leak Detection Company] | H33: [Leak Detection Company]
C34: [Clogged Drain Repair] | D34: [Clogged Drain Repair] | E34: [Clogged Drain Repair] | F34: [Clogged Drain Repair] | G34: [Underground Leak Detection] | H34: [Underground Leak Detection]
C35: "Geyser Repair Johannesburg" | D35: "Geyser Repair Johannesburg" | E35: "Geyser Repair Johannesburg" | F35: "Geyser Repair Johannesburg" | G35: "Geyser Repair Johannesburg" | H35: "Blocked Drain Plumber"
C36: "Burst Geyser Replacement" | D36: "Burst Geyser Replacement" | E36: "Burst Geyser Replacement" | F36: "Burst Geyser Replacement" | G36: "Burst Geyser Replacement" | H36: "Drain Cleaning Services"
C37: "Solar Geyser Installers" | D37: "Solar Geyser Installers" | E37: "Solar Geyser Installers" | F37: "Solar Geyser Installers" | G37: "Solar Geyser Installers" | H37: "Unblock Sewer Line"
C38: "No Hot Water Plumber" | D38: "No Hot Water Plumber" | E38: "No Hot Water Plumber" | F38: "No Hot Water Plumber" | G38: "No Hot Water Plumber" | H38: "Clogged Drain Repair"
C39: [Geyser Repair Johannesburg] | D39: [Geyser Repair Johannesburg] | E39: [Geyser Repair Johannesburg] | F39: [Geyser Repair Johannesburg] | G39: [Geyser Repair Johannesburg] | H39: [Blocked Drain Plumber]
C40: [Burst Geyser Replacement] | D40: [Burst Geyser Replacement] | E40: [Burst Geyser Replacement] | F40: [Burst Geyser Replacement] | G40: [Burst Geyser Replacement] | H40: [Drain Cleaning Services]
C41: [Solar Geyser Installers] | D41: [Solar Geyser Installers] | E41: [Solar Geyser Installers] | F41: [Solar Geyser Installers] | G41: [Solar Geyser Installers] | H41: [Unblock Sewer Line]
C42: [No Hot Water Plumber] | D42: [No Hot Water Plumber] | E42: [No Hot Water Plumber] | F42: [No Hot Water Plumber] | G42: [No Hot Water Plumber] | H42: [Clogged Drain Repair]

Sheet Responsive Ads
C2: ='Ad Groups'!C3 -> Emergency Plumbing | E2: =IF('Ad Groups'!C4=0," ",'Ad Groups'!C4) -> Residential Plumbing | G2: =IF('Ad Groups'!C5=0," ",'Ad Groups'!C5) -> Commercial Plumbing | I2: =IF('Ad Groups'!C6=0," ",'Ad Groups'!C6) -> Leak Detection | K2: =IF('Ad Groups'!C7=0," ",'Ad Groups'!C7) -> Drain Cleaning | M2: =IF('Ad Groups'!C8=0," ",'Ad Groups'!C8) -> Geyser Replacement & Repairs | O2: =IF('Ad Groups'!C9=0," ",'Ad Groups'!C9) | Q2: =IF('Ad Groups'!C10=0," ",'Ad Groups'!C10) | S2: =IF('Campaign Settings'!B1=0," ",'Campaign Settings'!B1) | U2: =IF('Campaign Settings'!B2=0," ",'Campaign Settings'!B2) | W2: =IF('Campaign Settings'!B3=0," ",'Campaign Settings'!B3) -> Sandton, Gauteng, South Africa | Y2: =IF('Campaign Settings'!B4=0," ",'Campaign Settings'!B4) -> N/a | AA2: =IF('Campaign Settings'!B5=0," ",'Campaign Settings'!B5) | AC2: =IF('Campaign Settings'!B6=0," ",'Campaign Settings'!B6) | AE2: =IF('Campaign Settings'!B7=0," ",'Campaign Settings'!B7) | AG2: =IF('Campaign Settings'!B8=0," ",'Campaign Settings'!B8) | AI2: =IF('Campaign Settings'!B9=0," ",'Campaign Settings'!B9) | AK2: =IF('Campaign Settings'!B10=0," ",'Campaign Settings'!B10) -> See Keywords | AM2: =IF('Ad Groups'!C21=0," ",'Ad Groups'!C21) | AO2: =IF('Ad Groups'!C22=0," ",'Ad Groups'!C22) | AQ2: =IF('Ad Groups'!C23=0," ",'Ad Groups'!C23) | AS2: =IF('Ad Groups'!C24=0," ",'Ad Groups'!C24) | AU2: =IF('Ad Groups'!C25=0," ",'Ad Groups'!C25) | AW2: =IF('Ad Groups'!C26=0," ",'Ad Groups'!C26) | AY2: =IF('Ad Groups'!C27=0," ",'Ad Groups'!C27) | BA2: =IF('Ad Groups'!C28=0," ",'Ad Groups'!C28) | BC2: =IF('Ad Groups'!C29=0," ",'Ad Groups'!C29) | BE2: =IF('Ad Groups'!C30=0," ",'Ad Groups'!C30) | BG2: =IF('Ad Groups'!C31=0," ",'Ad Groups'!C31) | BI2: =IF('Ad Groups'!C32=0," ",'Ad Groups'!C32) | BK2: =IF('Ad Groups'!C33=0," ",'Ad Groups'!C33) | BM2: =IF('Ad Groups'!C34=0," ",'Ad Groups'!C34) | BO2: =IF('Ad Groups'!C35=0," ",'Ad Groups'!C35) | BQ2: =IF('Ad Groups'!C36=0," ",'Ad Groups'!C36) | BS2: =IF('Ad Groups'!C37=0," ",'Ad Groups'!C37) | BU2: =IF('Ad Groups'!C38=0," ",'Ad Groups'!C38) | BW2: =IF('Ad Groups'!C39=0," ",'Ad Groups'!C39) | BY2: =IF('Ad Groups'!C40=0," ",'Ad Groups'!C40) | CA2: =IF('Ad Groups'!C41=0," ",'Ad Groups'!C41) | CC2: =IF('Ad Groups'!C42=0," ",'Ad Groups'!C42) | CE2: =IF('Ad Groups'!C43=0," ",'Ad Groups'!C43) | CG2: =IF('Ad Groups'!C44=0," ",'Ad Groups'!C44) | CI2: =IF('Ad Groups'!C45=0," ",'Ad Groups'!C45) | CK2: =IF('Ad Groups'!C46=0," ",'Ad Groups'!C46) | CM2: =IF('Ad Groups'!C47=0," ",'Ad Groups'!C47) | CO2: =IF('Ad Groups'!C48=0," ",'Ad Groups'!C48) | CQ2: =IF('Ad Groups'!C49=0," ",'Ad Groups'!C49) | CS2: =IF('Ad Groups'!C50=0," ",'Ad Groups'!C50) | CU2: =IF('Ad Groups'!C51=0," ",'Ad Groups'!C51) | CW2: =IF('Ad Groups'!C52=0," ",'Ad Groups'!C52) | CY2: =IF('Ad Groups'!C53=0," ",'Ad Groups'!C53) | DA2: =IF('Ad Groups'!C54=0," ",'Ad Groups'!C54) | DC2: =IF('Ad Groups'!C55=0," ",'Ad Groups'!C55) | DE2: =IF('Ad Groups'!C56=0," ",'Ad Groups'!C56) | DG2: =IF('Ad Groups'!C57=0," ",'Ad Groups'!C57) | DI2: =IF('Ad Groups'!C58=0," ",'Ad Groups'!C58) | DK2: =IF('Ad Groups'!C59=0," ",'Ad Groups'!C59) | DM2: =IF('Ad Groups'!C60=0," ",'Ad Groups'!C60)
A3: Headline 1 (30) | B3: =IF(LEN(C3)=0,"",LEN(C3)) -> 25 | C3: Emergency Plumber Near Me | D3: =IF(LEN(E3)=0,"",LEN(E3)) -> 26 | E3: Local Residential Plumbers | F3: =IF(LEN(G3)=0,"",LEN(G3)) -> 19 | G3: Commercial Plumbers | H3: =IF(LEN(I3)=0,"",LEN(I3)) -> 20 | I3: Water Leak Detection | J3: =IF(LEN(K3)=0,"",LEN(K3)) -> 21 | K3: Blocked Drain Plumber | L3: =IF(LEN(M3)=0,"",LEN(M3)) -> 27 | M3: Geyser Repairs Johannesburg | N3: =IF(LEN(O3)=0,"",LEN(O3)) | P3: =IF(LEN(Q3)=0,"",LEN(Q3)) | R3: =IF(LEN(S3)=0,"",LEN(S3)) | T3: =IF(LEN(U3)=0,"",LEN(U3)) | V3: =IF(LEN(W3)=0,"",LEN(W3)) | X3: =IF(LEN(Y3)=0,"",LEN(Y3)) | Z3: =IF(LEN(AA3)=0,"",LEN(AA3)) | AB3: =IF(LEN(AC3)=0,"",LEN(AC3)) | AD3: =IF(LEN(AE3)=0,"",LEN(AE3)) | AF3: =IF(LEN(AG3)=0,"",LEN(AG3)) | AH3: =IF(LEN(AI3)=0,"",LEN(AI3)) | AJ3: =IF(LEN(AK3)=0,"",LEN(AK3)) | AL3: =IF(LEN(AM3)=0,"",LEN(AM3)) | AN3: =IF(LEN(AO3)=0,"",LEN(AO3)) | AP3: =IF(LEN(AQ3)=0,"",LEN(AQ3)) | AR3: =IF(LEN(AS3)=0,"",LEN(AS3)) | AT3: =IF(LEN(AU3)=0,"",LEN(AU3)) | AV3: =IF(LEN(AW3)=0,"",LEN(AW3)) | AX3: =IF(LEN(AY3)=0,"",LEN(AY3)) | AZ3: =IF(LEN(BA3)=0,"",LEN(BA3)) | BB3: =IF(LEN(BC3)=0,"",LEN(BC3)) | BD3: =IF(LEN(BE3)=0,"",LEN(BE3)) | BF3: =IF(LEN(BG3)=0,"",LEN(BG3)) | BH3: =IF(LEN(BI3)=0,"",LEN(BI3)) | BJ3: =IF(LEN(BK3)=0,"",LEN(BK3)) | BL3: =IF(LEN(BM3)=0,"",LEN(BM3)) | BN3: =IF(LEN(BO3)=0,"",LEN(BO3)) | BP3: =IF(LEN(BQ3)=0,"",LEN(BQ3)) | BR3: =IF(LEN(BS3)=0,"",LEN(BS3)) | BT3: =IF(LEN(BU3)=0,"",LEN(BU3)) | BV3: =IF(LEN(BW3)=0,"",LEN(BW3)) | BX3: =IF(LEN(BY3)=0,"",LEN(BY3)) | BZ3: =IF(LEN(CA3)=0,"",LEN(CA3)) | CB3: =IF(LEN(CC3)=0,"",LEN(CC3)) | CD3: =IF(LEN(CE3)=0,"",LEN(CE3)) | CF3: =IF(LEN(CG3)=0,"",LEN(CG3)) | CH3: =IF(LEN(CI3)=0,"",LEN(CI3)) | CJ3: =IF(LEN(CK3)=0,"",LEN(CK3)) | CL3: =IF(LEN(CM3)=0,"",LEN(CM3)) | CN3: =IF(LEN(CO3)=0,"",LEN(CO3)) | CP3: =IF(LEN(CQ3)=0,"",LEN(CQ3)) | CR3: =IF(LEN(CS3)=0,"",LEN(CS3)) | CT3: =IF(LEN(CU3)=0,"",LEN(CU3)) | CV3: =IF(LEN(CW3)=0,"",LEN(CW3)) | CX3: =IF(LEN(CY3)=0,"",LEN(CY3)) | CZ3: =IF(LEN(DA3)=0,"",LEN(DA3)) | DB3: =IF(LEN(DC3)=0,"",LEN(DC3)) | DD3: =IF(LEN(DE3)=0,"",LEN(DE3)) | DF3: =IF(LEN(DG3)=0,"",LEN(DG3)) | DH3: =IF(LEN(DI3)=0,"",LEN(DI3)) | DJ3: =IF(LEN(DK3)=0,"",LEN(DK3)) | DL3: =IF(LEN(DM3)=0,"",LEN(DM3)) | DN3: =IF(LEN(DO3)=0,"",LEN(DO3)) | DP3: =IF(LEN(DQ3)=0,"",LEN(DQ3))
A4: Headline 2 (30) | B4: =IF(LEN(C4)=0,"",LEN(C4)) -> 23 | C4: 24/7 Emergency Plumbing | D4: =IF(LEN(E4)=0,"",LEN(E4)) -> 22 | E4: Home Plumbing Services | F4: =IF(LEN(G4)=0,"",LEN(G4)) -> 23 | G4: Plumbing For Businesses | H4: =IF(LEN(I4)=0,"",LEN(I4)) -> 23 | I4: Find Hidden Water Leaks | J4: =IF(LEN(K4)=0,"",LEN(K4)) -> 27 | K4: Professional Drain Cleaning | L4: =IF(LEN(M4)=0,"",LEN(M4)) -> 24 | M4: Burst Geyser Replacement | N4: =IF(LEN(O4)=0,"",LEN(O4)) | P4: =IF(LEN(Q4)=0,"",LEN(Q4)) | R4: =IF(LEN(S4)=0,"",LEN(S4)) | T4: =IF(LEN(U4)=0,"",LEN(U4)) | V4: =IF(LEN(W4)=0,"",LEN(W4)) | X4: =IF(LEN(Y4)=0,"",LEN(Y4)) | Z4: =IF(LEN(AA4)=0,"",LEN(AA4)) | AB4: =IF(LEN(AC4)=0,"",LEN(AC4)) | AD4: =IF(LEN(AE4)=0,"",LEN(AE4)) | AF4: =IF(LEN(AG4)=0,"",LEN(AG4)) | AH4: =IF(LEN(AI4)=0,"",LEN(AI4)) | AJ4: =IF(LEN(AK4)=0,"",LEN(AK4)) | AL4: =IF(LEN(AM4)=0,"",LEN(AM4)) | AN4: =IF(LEN(AO4)=0,"",LEN(AO4)) | AP4: =IF(LEN(AQ4)=0,"",LEN(AQ4)) | AR4: =IF(LEN(AS4)=0,"",LEN(AS4)) | AT4: =IF(LEN(AU4)=0,"",LEN(AU4)) | AV4: =IF(LEN(AW4)=0,"",LEN(AW4)) | AX4: =IF(LEN(AY4)=0,"",LEN(AY4)) | AZ4: =IF(LEN(BA4)=0,"",LEN(BA4)) | BB4: =IF(LEN(BC4)=0,"",LEN(BC4)) | BD4: =IF(LEN(BE4)=0,"",LEN(BE4)) | BF4: =IF(LEN(BG4)=0,"",LEN(BG4)) | BH4: =IF(LEN(BI4)=0,"",LEN(BI4)) | BJ4: =IF(LEN(BK4)=0,"",LEN(BK4)) | BL4: =IF(LEN(BM4)=0,"",LEN(BM4)) | BN4: =IF(LEN(BO4)=0,"",LEN(BO4)) | BP4: =IF(LEN(BQ4)=0,"",LEN(BQ4)) | BR4: =IF(LEN(BS4)=0,"",LEN(BS4)) | BT4: =IF(LEN(BU4)=0,"",LEN(BU4)) | BV4: =IF(LEN(BW4)=0,"",LEN(BW4)) | BX4: =IF(LEN(BY4)=0,"",LEN(BY4)) | BZ4: =IF(LEN(CA4)=0,"",LEN(CA4)) | CB4: =IF(LEN(CC4)=0,"",LEN(CC4)) | CD4: =IF(LEN(CE4)=0,"",LEN(CE4)) | CF4: =IF(LEN(CG4)=0,"",LEN(CG4)) | CH4: =IF(LEN(CI4)=0,"",LEN(CI4)) | CJ4: =IF(LEN(CK4)=0,"",LEN(CK4)) | CL4: =IF(LEN(CM4)=0,"",LEN(CM4)) | CN4: =IF(LEN(CO4)=0,"",LEN(CO4)) | CP4: =IF(LEN(CQ4)=0,"",LEN(CQ4)) | CR4: =IF(LEN(CS4)=0,"",LEN(CS4)) | CT4: =IF(LEN(CU4)=0,"",LEN(CU4)) | CV4: =IF(LEN(CW4)=0,"",LEN(CW4)) | CX4: =IF(LEN(CY4)=0,"",LEN(CY4)) | CZ4: =IF(LEN(DA4)=0,"",LEN(DA4)) | DB4: =IF(LEN(DC4)=0,"",LEN(DC4)) | DD4: =IF(LEN(DE4)=0,"",LEN(DE4)) | DF4: =IF(LEN(DG4)=0,"",LEN(DG4)) | DH4: =IF(LEN(DI4)=0,"",LEN(DI4)) | DJ4: =IF(LEN(DK4)=0,"",LEN(DK4)) | DL4: =IF(LEN(DM4)=0,"",LEN(DM4)) | DN4: =IF(LEN(DO4)=0,"",LEN(DO4)) | DP4: =IF(LEN(DQ4)=0,"",LEN(DQ4))
A5: Headline 3 (30) | B5: =IF(LEN(C5)=0,"",LEN(C5)) -> 21 | C5: Burst Pipe Repair Now | D5: =IF(LEN(E5)=0,"",LEN(E5)) -> 26 | E5: Expert Toilet & Tap Repair | F5: =IF(LEN(G5)=0,"",LEN(G5)) -> 23 | G5: Office Plumbing Repairs | H5: =IF(LEN(I5)=0,"",LEN(I5)) -> 25 | I5: High Water Bill Solutions | J5: =IF(LEN(K5)=0,"",LEN(K5)) -> 24 | K5: Unblock Sewer Lines Fast | L5: =IF(LEN(M5)=0,"",LEN(M5)) -> 22 | M5: No Hot Water Solutions | N5: =IF(LEN(O5)=0,"",LEN(O5)) | P5: =IF(LEN(Q5)=0,"",LEN(Q5)) | R5: =IF(LEN(S5)=0,"",LEN(S5)) | T5: =IF(LEN(U5)=0,"",LEN(U5)) | V5: =IF(LEN(W5)=0,"",LEN(W5)) | X5: =IF(LEN(Y5)=0,"",LEN(Y5)) | Z5: =IF(LEN(AA5)=0,"",LEN(AA5)) | AB5: =IF(LEN(AC5)=0,"",LEN(AC5)) | AD5: =IF(LEN(AE5)=0,"",LEN(AE5)) | AF5: =IF(LEN(AG5)=0,"",LEN(AG5)) | AH5: =IF(LEN(AI5)=0,"",LEN(AI5)) | AJ5: =IF(LEN(AK5)=0,"",LEN(AK5)) | AL5: =IF(LEN(AM5)=0,"",LEN(AM5)) | AN5: =IF(LEN(AO5)=0,"",LEN(AO5)) | AP5: =IF(LEN(AQ5)=0,"",LEN(AQ5)) | AR5: =IF(LEN(AS5)=0,"",LEN(AS5)) | AT5: =IF(LEN(AU5)=0,"",LEN(AU5)) | AV5: =IF(LEN(AW5)=0,"",LEN(AW5)) | AX5: =IF(LEN(AY5)=0,"",LEN(AY5)) | AZ5: =IF(LEN(BA5)=0,"",LEN(BA5)) | BB5: =IF(LEN(BC5)=0,"",LEN(BC5)) | BD5: =IF(LEN(BE5)=0,"",LEN(BE5)) | BF5: =IF(LEN(BG5)=0,"",LEN(BG5)) | BH5: =IF(LEN(BI5)=0,"",LEN(BI5)) | BJ5: =IF(LEN(BK5)=0,"",LEN(BK5)) | BL5: =IF(LEN(BM5)=0,"",LEN(BM5)) | BN5: =IF(LEN(BO5)=0,"",LEN(BO5)) | BP5: =IF(LEN(BQ5)=0,"",LEN(BQ5)) | BR5: =IF(LEN(BS5)=0,"",LEN(BS5)) | BT5: =IF(LEN(BU5)=0,"",LEN(BU5)) | BV5: =IF(LEN(BW5)=0,"",LEN(BW5)) | BX5: =IF(LEN(BY5)=0,"",LEN(BY5)) | BZ5: =IF(LEN(CA5)=0,"",LEN(CA5)) | CB5: =IF(LEN(CC5)=0,"",LEN(CC5)) | CD5: =IF(LEN(CE5)=0,"",LEN(CE5)) | CF5: =IF(LEN(CG5)=0,"",LEN(CG5)) | CH5: =IF(LEN(CI5)=0,"",LEN(CI5)) | CJ5: =IF(LEN(CK5)=0,"",LEN(CK5)) | CL5: =IF(LEN(CM5)=0,"",LEN(CM5)) | CN5: =IF(LEN(CO5)=0,"",LEN(CO5)) | CP5: =IF(LEN(CQ5)=0,"",LEN(CQ5)) | CR5: =IF(LEN(CS5)=0,"",LEN(CS5)) | CT5: =IF(LEN(CU5)=0,"",LEN(CU5)) | CV5: =IF(LEN(CW5)=0,"",LEN(CW5)) | CX5: =IF(LEN(CY5)=0,"",LEN(CY5)) | CZ5: =IF(LEN(DA5)=0,"",LEN(DA5)) | DB5: =IF(LEN(DC5)=0,"",LEN(DC5)) | DD5: =IF(LEN(DE5)=0,"",LEN(DE5)) | DF5: =IF(LEN(DG5)=0,"",LEN(DG5)) | DH5: =IF(LEN(DI5)=0,"",LEN(DI5)) | DJ5: =IF(LEN(DK5)=0,"",LEN(DK5)) | DL5: =IF(LEN(DM5)=0,"",LEN(DM5)) | DN5: =IF(LEN(DO5)=0,"",LEN(DO5)) | DP5: =IF(LEN(DQ5)=0,"",LEN(DQ5))
A6: Headline 4 (30) | B6: =IF(LEN(C6)=0,"",LEN(C6)) -> 19 | C6: Fast Local Plumbers | D6: =IF(LEN(E6)=0,"",LEN(E6)) -> 28 | E6: Affordable Household Plumber | F6: =IF(LEN(G6)=0,"",LEN(G6)) -> 22 | G6: Commercial Contractors | H6: =IF(LEN(I6)=0,"",LEN(I6)) -> 23 | I6: Advanced Leak Detection | J6: =IF(LEN(K6)=0,"",LEN(K6)) -> 21 | K6: Clogged Drain Repairs | L6: =IF(LEN(M6)=0,"",LEN(M6)) -> 26 | M6: Geyser Element Replacement | N6: =IF(LEN(O6)=0,"",LEN(O6)) | P6: =IF(LEN(Q6)=0,"",LEN(Q6)) | R6: =IF(LEN(S6)=0,"",LEN(S6)) | T6: =IF(LEN(U6)=0,"",LEN(U6)) | V6: =IF(LEN(W6)=0,"",LEN(W6)) | X6: =IF(LEN(Y6)=0,"",LEN(Y6)) | Z6: =IF(LEN(AA6)=0,"",LEN(AA6)) | AB6: =IF(LEN(AC6)=0,"",LEN(AC6)) | AD6: =IF(LEN(AE6)=0,"",LEN(AE6)) | AF6: =IF(LEN(AG6)=0,"",LEN(AG6)) | AH6: =IF(LEN(AI6)=0,"",LEN(AI6)) | AJ6: =IF(LEN(AK6)=0,"",LEN(AK6)) | AL6: =IF(LEN(AM6)=0,"",LEN(AM6)) | AN6: =IF(LEN(AO6)=0,"",LEN(AO6)) | AP6: =IF(LEN(AQ6)=0,"",LEN(AQ6)) | AR6: =IF(LEN(AS6)=0,"",LEN(AS6)) | AT6: =IF(LEN(AU6)=0,"",LEN(AU6)) | AV6: =IF(LEN(AW6)=0,"",LEN(AW6)) | AX6: =IF(LEN(AY6)=0,"",LEN(AY6)) | AZ6: =IF(LEN(BA6)=0,"",LEN(BA6)) | BB6: =IF(LEN(BC6)=0,"",LEN(BC6)) | BD6: =IF(LEN(BE6)=0,"",LEN(BE6)) | BF6: =IF(LEN(BG6)=0,"",LEN(BG6)) | BH6: =IF(LEN(BI6)=0,"",LEN(BI6)) | BJ6: =IF(LEN(BK6)=0,"",LEN(BK6)) | BL6: =IF(LEN(BM6)=0,"",LEN(BM6)) | BN6: =IF(LEN(BO6)=0,"",LEN(BO6)) | BP6: =IF(LEN(BQ6)=0,"",LEN(BQ6)) | BR6: =IF(LEN(BS6)=0,"",LEN(BS6)) | BT6: =IF(LEN(BU6)=0,"",LEN(BU6)) | BV6: =IF(LEN(BW6)=0,"",LEN(BW6)) | BX6: =IF(LEN(BY6)=0,"",LEN(BY6)) | BZ6: =IF(LEN(CA6)=0,"",LEN(CA6)) | CB6: =IF(LEN(CC6)=0,"",LEN(CC6)) | CD6: =IF(LEN(CE6)=0,"",LEN(CE6)) | CF6: =IF(LEN(CG6)=0,"",LEN(CG6)) | CH6: =IF(LEN(CI6)=0,"",LEN(CI6)) | CJ6: =IF(LEN(CK6)=0,"",LEN(CK6)) | CL6: =IF(LEN(CM6)=0,"",LEN(CM6)) | CN6: =IF(LEN(CO6)=0,"",LEN(CO6)) | CP6: =IF(LEN(CQ6)=0,"",LEN(CQ6)) | CR6: =IF(LEN(CS6)=0,"",LEN(CS6)) | CT6: =IF(LEN(CU6)=0,"",LEN(CU6)) | CV6: =IF(LEN(CW6)=0,"",LEN(CW6)) | CX6: =IF(LEN(CY6)=0,"",LEN(CY6)) | CZ6: =IF(LEN(DA6)=0,"",LEN(DA6)) | DB6: =IF(LEN(DC6)=0,"",LEN(DC6)) | DD6: =IF(LEN(DE6)=0,"",LEN(DE6)) | DF6: =IF(LEN(DG6)=0,"",LEN(DG6)) | DH6: =IF(LEN(DI6)=0,"",LEN(DI6)) | DJ6: =IF(LEN(DK6)=0,"",LEN(DK6)) | DL6: =IF(LEN(DM6)=0,"",LEN(DM6)) | DN6: =IF(LEN(DO6)=0,"",LEN(DO6)) | DP6: =IF(LEN(DQ6)=0,"",LEN(DQ6))
A7: Headline 5 (30) | B7: =IF(LEN(C7)=0,"",LEN(C7)) -> 24 | C7: Available 24 Hours A Day | D7: =IF(LEN(E7)=0,"",LEN(E7)) -> 20 | E7: Trusted Home Repairs | F7: =IF(LEN(G7)=0,"",LEN(G7)) -> 25 | G7: Property Maintenance Care | H7: =IF(LEN(I7)=0,"",LEN(I7)) -> 21 | I7: Stop Water Leaks Fast | J7: =IF(LEN(K7)=0,"",LEN(K7)) -> 24 | K7: Clear Blocked Drains Now | L7: =IF(LEN(M7)=0,"",LEN(M7)) -> 25 | M7: Solar Geyser Installation | N7: =IF(LEN(O7)=0,"",LEN(O7)) | P7: =IF(LEN(Q7)=0,"",LEN(Q7)) | R7: =IF(LEN(S7)=0,"",LEN(S7)) | T7: =IF(LEN(U7)=0,"",LEN(U7)) | V7: =IF(LEN(W7)=0,"",LEN(W7)) | X7: =IF(LEN(Y7)=0,"",LEN(Y7)) | Z7: =IF(LEN(AA7)=0,"",LEN(AA7)) | AB7: =IF(LEN(AC7)=0,"",LEN(AC7)) | AD7: =IF(LEN(AE7)=0,"",LEN(AE7)) | AF7: =IF(LEN(AG7)=0,"",LEN(AG7)) | AH7: =IF(LEN(AI7)=0,"",LEN(AI7)) | AJ7: =IF(LEN(AK7)=0,"",LEN(AK7)) | AL7: =IF(LEN(AM7)=0,"",LEN(AM7)) | AN7: =IF(LEN(AO7)=0,"",LEN(AO7)) | AP7: =IF(LEN(AQ7)=0,"",LEN(AQ7)) | AR7: =IF(LEN(AS7)=0,"",LEN(AS7)) | AT7: =IF(LEN(AU7)=0,"",LEN(AU7)) | AV7: =IF(LEN(AW7)=0,"",LEN(AW7)) | AX7: =IF(LEN(AY7)=0,"",LEN(AY7)) | AZ7: =IF(LEN(BA7)=0,"",LEN(BA7)) | BB7: =IF(LEN(BC7)=0,"",LEN(BC7)) | BD7: =IF(LEN(BE7)=0,"",LEN(BE7)) | BF7: =IF(LEN(BG7)=0,"",LEN(BG7)) | BH7: =IF(LEN(BI7)=0,"",LEN(BI7)) | BJ7: =IF(LEN(BK7)=0,"",LEN(BK7)) | BL7: =IF(LEN(BM7)=0,"",LEN(BM7)) | BN7: =IF(LEN(BO7)=0,"",LEN(BO7)) | BP7: =IF(LEN(BQ7)=0,"",LEN(BQ7)) | BR7: =IF(LEN(BS7)=0,"",LEN(BS7)) | BT7: =IF(LEN(BU7)=0,"",LEN(BU7)) | BV7: =IF(LEN(BW7)=0,"",LEN(BW7)) | BX7: =IF(LEN(BY7)=0,"",LEN(BY7)) | BZ7: =IF(LEN(CA7)=0,"",LEN(CA7)) | CB7: =IF(LEN(CC7)=0,"",LEN(CC7)) | CD7: =IF(LEN(CE7)=0,"",LEN(CE7)) | CF7: =IF(LEN(CG7)=0,"",LEN(CG7)) | CH7: =IF(LEN(CI7)=0,"",LEN(CI7)) | CJ7: =IF(LEN(CK7)=0,"",LEN(CK7)) | CL7: =IF(LEN(CM7)=0,"",LEN(CM7)) | CN7: =IF(LEN(CO7)=0,"",LEN(CO7)) | CP7: =IF(LEN(CQ7)=0,"",LEN(CQ7)) | CR7: =IF(LEN(CS7)=0,"",LEN(CS7)) | CT7: =IF(LEN(CU7)=0,"",LEN(CU7)) | CV7: =IF(LEN(CW7)=0,"",LEN(CW7)) | CX7: =IF(LEN(CY7)=0,"",LEN(CY7)) | CZ7: =IF(LEN(DA7)=0,"",LEN(DA7)) | DB7: =IF(LEN(DC7)=0,"",LEN(DC7)) | DD7: =IF(LEN(DE7)=0,"",LEN(DE7)) | DF7: =IF(LEN(DG7)=0,"",LEN(DG7)) | DH7: =IF(LEN(DI7)=0,"",LEN(DI7)) | DJ7: =IF(LEN(DK7)=0,"",LEN(DK7)) | DL7: =IF(LEN(DM7)=0,"",LEN(DM7)) | DN7: =IF(LEN(DO7)=0,"",LEN(DO7)) | DP7: =IF(LEN(DQ7)=0,"",LEN(DQ7))
A8: Headline 6 (30) | B8: =IF(LEN(C8)=0,"",LEN(C8)) -> 22 | C8: Rapid On-Site Response | D8: =IF(LEN(E8)=0,"",LEN(E8)) -> 24 | E8: Fix Leaky Taps & Toilets | F8: =IF(LEN(G8)=0,"",LEN(G8)) -> 27 | G8: Industrial Plumbing Experts | H8: =IF(LEN(I8)=0,"",LEN(I8)) -> 22 | I8: Accurate Leak Locating | J8: =IF(LEN(K8)=0,"",LEN(K8)) -> 27 | K8: High-Pressure Drain Jetting | L8: =IF(LEN(M8)=0,"",LEN(M8)) -> 25 | M8: Expert Geyser Technicians | N8: =IF(LEN(O8)=0,"",LEN(O8)) | P8: =IF(LEN(Q8)=0,"",LEN(Q8)) | R8: =IF(LEN(S8)=0,"",LEN(S8)) | T8: =IF(LEN(U8)=0,"",LEN(U8)) | V8: =IF(LEN(W8)=0,"",LEN(W8)) | X8: =IF(LEN(Y8)=0,"",LEN(Y8)) | Z8: =IF(LEN(AA8)=0,"",LEN(AA8)) | AB8: =IF(LEN(AC8)=0,"",LEN(AC8)) | AD8: =IF(LEN(AE8)=0,"",LEN(AE8)) | AF8: =IF(LEN(AG8)=0,"",LEN(AG8)) | AH8: =IF(LEN(AI8)=0,"",LEN(AI8)) | AJ8: =IF(LEN(AK8)=0,"",LEN(AK8)) | AL8: =IF(LEN(AM8)=0,"",LEN(AM8)) | AN8: =IF(LEN(AO8)=0,"",LEN(AO8)) | AP8: =IF(LEN(AQ8)=0,"",LEN(AQ8)) | AR8: =IF(LEN(AS8)=0,"",LEN(AS8)) | AT8: =IF(LEN(AU8)=0,"",LEN(AU8)) | AV8: =IF(LEN(AW8)=0,"",LEN(AW8)) | AX8: =IF(LEN(AY8)=0,"",LEN(AY8)) | AZ8: =IF(LEN(BA8)=0,"",LEN(BA8)) | BB8: =IF(LEN(BC8)=0,"",LEN(BC8)) | BD8: =IF(LEN(BE8)=0,"",LEN(BE8)) | BF8: =IF(LEN(BG8)=0,"",LEN(BG8)) | BH8: =IF(LEN(BI8)=0,"",LEN(BI8)) | BJ8: =IF(LEN(BK8)=0,"",LEN(BK8)) | BL8: =IF(LEN(BM8)=0,"",LEN(BM8)) | BN8: =IF(LEN(BO8)=0,"",LEN(BO8)) | BP8: =IF(LEN(BQ8)=0,"",LEN(BQ8)) | BR8: =IF(LEN(BS8)=0,"",LEN(BS8)) | BT8: =IF(LEN(BU8)=0,"",LEN(BU8)) | BV8: =IF(LEN(BW8)=0,"",LEN(BW8)) | BX8: =IF(LEN(BY8)=0,"",LEN(BY8)) | BZ8: =IF(LEN(CA8)=0,"",LEN(CA8)) | CB8: =IF(LEN(CC8)=0,"",LEN(CC8)) | CD8: =IF(LEN(CE8)=0,"",LEN(CE8)) | CF8: =IF(LEN(CG8)=0,"",LEN(CG8)) | CH8: =IF(LEN(CI8)=0,"",LEN(CI8)) | CJ8: =IF(LEN(CK8)=0,"",LEN(CK8)) | CL8: =IF(LEN(CM8)=0,"",LEN(CM8)) | CN8: =IF(LEN(CO8)=0,"",LEN(CO8)) | CP8: =IF(LEN(CQ8)=0,"",LEN(CQ8)) | CR8: =IF(LEN(CS8)=0,"",LEN(CS8)) | CT8: =IF(LEN(CU8)=0,"",LEN(CU8)) | CV8: =IF(LEN(CW8)=0,"",LEN(CW8)) | CX8: =IF(LEN(CY8)=0,"",LEN(CY8)) | CZ8: =IF(LEN(DA8)=0,"",LEN(DA8)) | DB8: =IF(LEN(DC8)=0,"",LEN(DC8)) | DD8: =IF(LEN(DE8)=0,"",LEN(DE8)) | DF8: =IF(LEN(DG8)=0,"",LEN(DG8)) | DH8: =IF(LEN(DI8)=0,"",LEN(DI8)) | DJ8: =IF(LEN(DK8)=0,"",LEN(DK8)) | DL8: =IF(LEN(DM8)=0,"",LEN(DM8)) | DN8: =IF(LEN(DO8)=0,"",LEN(DO8)) | DP8: =IF(LEN(DQ8)=0,"",LEN(DQ8))
A9: Headline 7 (30) | B9: =IF(LEN(C9)=0,"",LEN(C9)) -> 27 | C9: Fix Your Plumbing Emergency | D9: =IF(LEN(E9)=0,"",LEN(E9)) -> 25 | E9: Professional Home Service | F9: =IF(LEN(G9)=0,"",LEN(G9)) -> 26 | G9: Minimize Business Downtime | H9: =IF(LEN(I9)=0,"",LEN(I9)) -> 24 | I9: Damp Wall Leak Detection | J9: =IF(LEN(K9)=0,"",LEN(K9)) -> 24 | K9: Sink & Toilet Unblocking | L9: =IF(LEN(M9)=0,"",LEN(M9)) -> 24 | M9: Fix Your Hot Water Today | N9: =IF(LEN(O9)=0,"",LEN(O9)) | P9: =IF(LEN(Q9)=0,"",LEN(Q9)) | R9: =IF(LEN(S9)=0,"",LEN(S9)) | T9: =IF(LEN(U9)=0,"",LEN(U9)) | V9: =IF(LEN(W9)=0,"",LEN(W9)) | X9: =IF(LEN(Y9)=0,"",LEN(Y9)) | Z9: =IF(LEN(AA9)=0,"",LEN(AA9)) | AB9: =IF(LEN(AC9)=0,"",LEN(AC9)) | AD9: =IF(LEN(AE9)=0,"",LEN(AE9)) | AF9: =IF(LEN(AG9)=0,"",LEN(AG9)) | AH9: =IF(LEN(AI9)=0,"",LEN(AI9)) | AJ9: =IF(LEN(AK9)=0,"",LEN(AK9)) | AL9: =IF(LEN(AM9)=0,"",LEN(AM9)) | AN9: =IF(LEN(AO9)=0,"",LEN(AO9)) | AP9: =IF(LEN(AQ9)=0,"",LEN(AQ9)) | AR9: =IF(LEN(AS9)=0,"",LEN(AS9)) | AT9: =IF(LEN(AU9)=0,"",LEN(AU9)) | AV9: =IF(LEN(AW9)=0,"",LEN(AW9)) | AX9: =IF(LEN(AY9)=0,"",LEN(AY9)) | AZ9: =IF(LEN(BA9)=0,"",LEN(BA9)) | BB9: =IF(LEN(BC9)=0,"",LEN(BC9)) | BD9: =IF(LEN(BE9)=0,"",LEN(BE9)) | BF9: =IF(LEN(BG9)=0,"",LEN(BG9)) | BH9: =IF(LEN(BI9)=0,"",LEN(BI9)) | BJ9: =IF(LEN(BK9)=0,"",LEN(BK9)) | BL9: =IF(LEN(BM9)=0,"",LEN(BM9)) | BN9: =IF(LEN(BO9)=0,"",LEN(BO9)) | BP9: =IF(LEN(BQ9)=0,"",LEN(BQ9)) | BR9: =IF(LEN(BS9)=0,"",LEN(BS9)) | BT9: =IF(LEN(BU9)=0,"",LEN(BU9)) | BV9: =IF(LEN(BW9)=0,"",LEN(BW9)) | BX9: =IF(LEN(BY9)=0,"",LEN(BY9)) | BZ9: =IF(LEN(CA9)=0,"",LEN(CA9)) | CB9: =IF(LEN(CC9)=0,"",LEN(CC9)) | CD9: =IF(LEN(CE9)=0,"",LEN(CE9)) | CF9: =IF(LEN(CG9)=0,"",LEN(CG9)) | CH9: =IF(LEN(CI9)=0,"",LEN(CI9)) | CJ9: =IF(LEN(CK9)=0,"",LEN(CK9)) | CL9: =IF(LEN(CM9)=0,"",LEN(CM9)) | CN9: =IF(LEN(CO9)=0,"",LEN(CO9)) | CP9: =IF(LEN(CQ9)=0,"",LEN(CQ9)) | CR9: =IF(LEN(CS9)=0,"",LEN(CS9)) | CT9: =IF(LEN(CU9)=0,"",LEN(CU9)) | CV9: =IF(LEN(CW9)=0,"",LEN(CW9)) | CX9: =IF(LEN(CY9)=0,"",LEN(CY9)) | CZ9: =IF(LEN(DA9)=0,"",LEN(DA9)) | DB9: =IF(LEN(DC9)=0,"",LEN(DC9)) | DD9: =IF(LEN(DE9)=0,"",LEN(DE9)) | DF9: =IF(LEN(DG9)=0,"",LEN(DG9)) | DH9: =IF(LEN(DI9)=0,"",LEN(DI9)) | DJ9: =IF(LEN(DK9)=0,"",LEN(DK9)) | DL9: =IF(LEN(DM9)=0,"",LEN(DM9)) | DN9: =IF(LEN(DO9)=0,"",LEN(DO9)) | DP9: =IF(LEN(DQ9)=0,"",LEN(DQ9))
A10: Headline 8 (30) | B10: =IF(LEN(C10)=0,"",LEN(C10)) -> 25 | C10: No Extra After-Hours Fees | D10: =IF(LEN(E10)=0,"",LEN(E10)) -> 26 | E10: Reliable Plumbers Near You | F10: =IF(LEN(G10)=0,"",LEN(G10)) -> 27 | G10: Reliable Commercial Service | H10: =IF(LEN(I10)=0,"",LEN(I10)) -> 25 | I10: Non-Invasive Leak Testing | J10: =IF(LEN(K10)=0,"",LEN(K10)) -> 25 | K10: Fast Emergency Drain Care | L10: =IF(LEN(M10)=0,"",LEN(M10)) -> 26 | M10: Approved Geyser Installers | N10: =IF(LEN(O10)=0,"",LEN(O10)) | P10: =IF(LEN(Q10)=0,"",LEN(Q10)) | R10: =IF(LEN(S10)=0,"",LEN(S10)) | T10: =IF(LEN(U10)=0,"",LEN(U10)) | V10: =IF(LEN(W10)=0,"",LEN(W10)) | X10: =IF(LEN(Y10)=0,"",LEN(Y10)) | Z10: =IF(LEN(AA10)=0,"",LEN(AA10)) | AB10: =IF(LEN(AC10)=0,"",LEN(AC10)) | AD10: =IF(LEN(AE10)=0,"",LEN(AE10)) | AF10: =IF(LEN(AG10)=0,"",LEN(AG10)) | AH10: =IF(LEN(AI10)=0,"",LEN(AI10)) | AJ10: =IF(LEN(AK10)=0,"",LEN(AK10)) | AL10: =IF(LEN(AM10)=0,"",LEN(AM10)) | AN10: =IF(LEN(AO10)=0,"",LEN(AO10)) | AP10: =IF(LEN(AQ10)=0,"",LEN(AQ10)) | AR10: =IF(LEN(AS10)=0,"",LEN(AS10)) | AT10: =IF(LEN(AU10)=0,"",LEN(AU10)) | AV10: =IF(LEN(AW10)=0,"",LEN(AW10)) | AX10: =IF(LEN(AY10)=0,"",LEN(AY10)) | AZ10: =IF(LEN(BA10)=0,"",LEN(BA10)) | BB10: =IF(LEN(BC10)=0,"",LEN(BC10)) | BD10: =IF(LEN(BE10)=0,"",LEN(BE10)) | BF10: =IF(LEN(BG10)=0,"",LEN(BG10)) | BH10: =IF(LEN(BI10)=0,"",LEN(BI10)) | BJ10: =IF(LEN(BK10)=0,"",LEN(BK10)) | BL10: =IF(LEN(BM10)=0,"",LEN(BM10)) | BN10: =IF(LEN(BO10)=0,"",LEN(BO10)) | BP10: =IF(LEN(BQ10)=0,"",LEN(BQ10)) | BR10: =IF(LEN(BS10)=0,"",LEN(BS10)) | BT10: =IF(LEN(BU10)=0,"",LEN(BU10)) | BV10: =IF(LEN(BW10)=0,"",LEN(BW10)) | BX10: =IF(LEN(BY10)=0,"",LEN(BY10)) | BZ10: =IF(LEN(CA10)=0,"",LEN(CA10)) | CB10: =IF(LEN(CC10)=0,"",LEN(CC10)) | CD10: =IF(LEN(CE10)=0,"",LEN(CE10)) | CF10: =IF(LEN(CG10)=0,"",LEN(CG10)) | CH10: =IF(LEN(CI10)=0,"",LEN(CI10)) | CJ10: =IF(LEN(CK10)=0,"",LEN(CK10)) | CL10: =IF(LEN(CM10)=0,"",LEN(CM10)) | CN10: =IF(LEN(CO10)=0,"",LEN(CO10)) | CP10: =IF(LEN(CQ10)=0,"",LEN(CQ10)) | CR10: =IF(LEN(CS10)=0,"",LEN(CS10)) | CT10: =IF(LEN(CU10)=0,"",LEN(CU10)) | CV10: =IF(LEN(CW10)=0,"",LEN(CW10)) | CX10: =IF(LEN(CY10)=0,"",LEN(CY10)) | CZ10: =IF(LEN(DA10)=0,"",LEN(DA10)) | DB10: =IF(LEN(DC10)=0,"",LEN(DC10)) | DD10: =IF(LEN(DE10)=0,"",LEN(DE10)) | DF10: =IF(LEN(DG10)=0,"",LEN(DG10)) | DH10: =IF(LEN(DI10)=0,"",LEN(DI10)) | DJ10: =IF(LEN(DK10)=0,"",LEN(DK10)) | DL10: =IF(LEN(DM10)=0,"",LEN(DM10)) | DN10: =IF(LEN(DO10)=0,"",LEN(DO10)) | DP10: =IF(LEN(DQ10)=0,"",LEN(DQ10))
A11: Headline 9 (30) | B11: =IF(LEN(C11)=0,"",LEN(C11)) -> 21 | C11: Trusted Local Experts | D11: =IF(LEN(E11)=0,"",LEN(E11)) -> 24 | E11: Quality Residential Care | F11: =IF(LEN(G11)=0,"",LEN(G11)) -> 26 | G11: Licensed Business Plumbers | H11: =IF(LEN(I11)=0,"",LEN(I11)) -> 19 | I11: Pinpoint Pipe Leaks | J11: =IF(LEN(K11)=0,"",LEN(K11)) -> 24 | K11: Root Removal From Drains | L11: =IF(LEN(M11)=0,"",LEN(M11)) -> 20 | M11: Geyser Valve Repairs | N11: =IF(LEN(O11)=0,"",LEN(O11)) | P11: =IF(LEN(Q11)=0,"",LEN(Q11)) | R11: =IF(LEN(S11)=0,"",LEN(S11)) | T11: =IF(LEN(U11)=0,"",LEN(U11)) | V11: =IF(LEN(W11)=0,"",LEN(W11)) | X11: =IF(LEN(Y11)=0,"",LEN(Y11)) | Z11: =IF(LEN(AA11)=0,"",LEN(AA11)) | AB11: =IF(LEN(AC11)=0,"",LEN(AC11)) | AD11: =IF(LEN(AE11)=0,"",LEN(AE11)) | AF11: =IF(LEN(AG11)=0,"",LEN(AG11)) | AH11: =IF(LEN(AI11)=0,"",LEN(AI11)) | AJ11: =IF(LEN(AK11)=0,"",LEN(AK11)) | AL11: =IF(LEN(AM11)=0,"",LEN(AM11)) | AN11: =IF(LEN(AO11)=0,"",LEN(AO11)) | AP11: =IF(LEN(AQ11)=0,"",LEN(AQ11)) | AR11: =IF(LEN(AS11)=0,"",LEN(AS11)) | AT11: =IF(LEN(AU11)=0,"",LEN(AU11)) | AV11: =IF(LEN(AW11)=0,"",LEN(AW11)) | AX11: =IF(LEN(AY11)=0,"",LEN(AY11)) | AZ11: =IF(LEN(BA11)=0,"",LEN(BA11)) | BB11: =IF(LEN(BC11)=0,"",LEN(BC11)) | BD11: =IF(LEN(BE11)=0,"",LEN(BE11)) | BF11: =IF(LEN(BG11)=0,"",LEN(BG11)) | BH11: =IF(LEN(BI11)=0,"",LEN(BI11)) | BJ11: =IF(LEN(BK11)=0,"",LEN(BK11)) | BL11: =IF(LEN(BM11)=0,"",LEN(BM11)) | BN11: =IF(LEN(BO11)=0,"",LEN(BO11)) | BP11: =IF(LEN(BQ11)=0,"",LEN(BQ11)) | BR11: =IF(LEN(BS11)=0,"",LEN(BS11)) | BT11: =IF(LEN(BU11)=0,"",LEN(BU11)) | BV11: =IF(LEN(BW11)=0,"",LEN(BW11)) | BX11: =IF(LEN(BY11)=0,"",LEN(BY11)) | BZ11: =IF(LEN(CA11)=0,"",LEN(CA11)) | CB11: =IF(LEN(CC11)=0,"",LEN(CC11)) | CD11: =IF(LEN(CE11)=0,"",LEN(CE11)) | CF11: =IF(LEN(CG11)=0,"",LEN(CG11)) | CH11: =IF(LEN(CI11)=0,"",LEN(CI11)) | CJ11: =IF(LEN(CK11)=0,"",LEN(CK11)) | CL11: =IF(LEN(CM11)=0,"",LEN(CM11)) | CN11: =IF(LEN(CO11)=0,"",LEN(CO11)) | CP11: =IF(LEN(CQ11)=0,"",LEN(CQ11)) | CR11: =IF(LEN(CS11)=0,"",LEN(CS11)) | CT11: =IF(LEN(CU11)=0,"",LEN(CU11)) | CV11: =IF(LEN(CW11)=0,"",LEN(CW11)) | CX11: =IF(LEN(CY11)=0,"",LEN(CY11)) | CZ11: =IF(LEN(DA11)=0,"",LEN(DA11)) | DB11: =IF(LEN(DC11)=0,"",LEN(DC11)) | DD11: =IF(LEN(DE11)=0,"",LEN(DE11)) | DF11: =IF(LEN(DG11)=0,"",LEN(DG11)) | DH11: =IF(LEN(DI11)=0,"",LEN(DI11)) | DJ11: =IF(LEN(DK11)=0,"",LEN(DK11)) | DL11: =IF(LEN(DM11)=0,"",LEN(DM11)) | DN11: =IF(LEN(DO11)=0,"",LEN(DO11)) | DP11: =IF(LEN(DQ11)=0,"",LEN(DQ11))
A12: Headline 10 (30) | B12: =IF(LEN(C12)=0,"",LEN(C12)) -> 23 | C12: Call Our Emergency Team | D12: =IF(LEN(E12)=0,"",LEN(E12)) -> 25 | E12: Book A Home Plumber Today | F12: =IF(LEN(G12)=0,"",LEN(G12)) -> 25 | G12: Corporate Plumbing Audits | H12: =IF(LEN(I12)=0,"",LEN(I12)) -> 20 | I12: Expert Leak Locators | J12: =IF(LEN(K12)=0,"",LEN(K12)) -> 24 | K12: Clear Your Clogged Pipes | L12: =IF(LEN(M12)=0,"",LEN(M12)) -> 24 | M12: Emergency Geyser Service | N12: =IF(LEN(O12)=0,"",LEN(O12)) | P12: =IF(LEN(Q12)=0,"",LEN(Q12)) | R12: =IF(LEN(S12)=0,"",LEN(S12)) | T12: =IF(LEN(U12)=0,"",LEN(U12)) | V12: =IF(LEN(W12)=0,"",LEN(W12)) | X12: =IF(LEN(Y12)=0,"",LEN(Y12)) | Z12: =IF(LEN(AA12)=0,"",LEN(AA12)) | AB12: =IF(LEN(AC12)=0,"",LEN(AC12)) | AD12: =IF(LEN(AE12)=0,"",LEN(AE12)) | AF12: =IF(LEN(AG12)=0,"",LEN(AG12)) | AH12: =IF(LEN(AI12)=0,"",LEN(AI12)) | AJ12: =IF(LEN(AK12)=0,"",LEN(AK12)) | AL12: =IF(LEN(AM12)=0,"",LEN(AM12)) | AN12: =IF(LEN(AO12)=0,"",LEN(AO12)) | AP12: =IF(LEN(AQ12)=0,"",LEN(AQ12)) | AR12: =IF(LEN(AS12)=0,"",LEN(AS12)) | AT12: =IF(LEN(AU12)=0,"",LEN(AU12)) | AV12: =IF(LEN(AW12)=0,"",LEN(AW12)) | AX12: =IF(LEN(AY12)=0,"",LEN(AY12)) | AZ12: =IF(LEN(BA12)=0,"",LEN(BA12)) | BB12: =IF(LEN(BC12)=0,"",LEN(BC12)) | BD12: =IF(LEN(BE12)=0,"",LEN(BE12)) | BF12: =IF(LEN(BG12)=0,"",LEN(BG12)) | BH12: =IF(LEN(BI12)=0,"",LEN(BI12)) | BJ12: =IF(LEN(BK12)=0,"",LEN(BK12)) | BL12: =IF(LEN(BM12)=0,"",LEN(BM12)) | BN12: =IF(LEN(BO12)=0,"",LEN(BO12)) | BP12: =IF(LEN(BQ12)=0,"",LEN(BQ12)) | BR12: =IF(LEN(BS12)=0,"",LEN(BS12)) | BT12: =IF(LEN(BU12)=0,"",LEN(BU12)) | BV12: =IF(LEN(BW12)=0,"",LEN(BW12)) | BX12: =IF(LEN(BY12)=0,"",LEN(BY12)) | BZ12: =IF(LEN(CA12)=0,"",LEN(CA12)) | CB12: =IF(LEN(CC12)=0,"",LEN(CC12)) | CD12: =IF(LEN(CE12)=0,"",LEN(CE12)) | CF12: =IF(LEN(CG12)=0,"",LEN(CG12)) | CH12: =IF(LEN(CI12)=0,"",LEN(CI12)) | CJ12: =IF(LEN(CK12)=0,"",LEN(CK12)) | CL12: =IF(LEN(CM12)=0,"",LEN(CM12)) | CN12: =IF(LEN(CO12)=0,"",LEN(CO12)) | CP12: =IF(LEN(CQ12)=0,"",LEN(CQ12)) | CR12: =IF(LEN(CS12)=0,"",LEN(CS12)) | CT12: =IF(LEN(CU12)=0,"",LEN(CU12)) | CV12: =IF(LEN(CW12)=0,"",LEN(CW12)) | CX12: =IF(LEN(CY12)=0,"",LEN(CY12)) | CZ12: =IF(LEN(DA12)=0,"",LEN(DA12)) | DB12: =IF(LEN(DC12)=0,"",LEN(DC12)) | DD12: =IF(LEN(DE12)=0,"",LEN(DE12)) | DF12: =IF(LEN(DG12)=0,"",LEN(DG12)) | DH12: =IF(LEN(DI12)=0,"",LEN(DI12)) | DJ12: =IF(LEN(DK12)=0,"",LEN(DK12)) | DL12: =IF(LEN(DM12)=0,"",LEN(DM12)) | DN12: =IF(LEN(DO12)=0,"",LEN(DO12)) | DP12: =IF(LEN(DQ12)=0,"",LEN(DQ12))
A13: Description 1 (90) | B13: =IF(LEN(C13)=0,"",LEN(C13)) -> 86 | C13: Burst Pipe Or Severe Leak? Our Emergency Plumbers Are On Standby 24/7 To Help You Now. | D13: =IF(LEN(E13)=0,"",LEN(E13)) -> 84 | E13: From Leaky Taps To Full Household Plumbing Installations, We Keep Your Home Running. | F13: =IF(LEN(G13)=0,"",LEN(G13)) -> 90 | G13: Expert Commercial Plumbing Solutions Designed To Keep Your Business Operating Efficiently. | H13: =IF(LEN(I13)=0,"",LEN(I13)) -> 90 | I13: High Water Bill? We Find Hidden Underground And In-Wall Leaks Without Breaking Your Walls. | J13: =IF(LEN(K13)=0,"",LEN(K13)) -> 87 | K13: Overflowing Drains Or Blocked Toilets? We Clear Stubborn Blockages Rapidly And Cleanly. | L13: =IF(LEN(M13)=0,"",LEN(M13)) -> 90 | M13: No Hot Water Or A Leaking Geyser? Our Certified Technicians Repair All Major Brands Today. | N13: =IF(LEN(O13)=0,"",LEN(O13)) | P13: =IF(LEN(Q13)=0,"",LEN(Q13)) | R13: =IF(LEN(S13)=0,"",LEN(S13)) | T13: =IF(LEN(U13)=0,"",LEN(U13)) | V13: =IF(LEN(W13)=0,"",LEN(W13)) | X13: =IF(LEN(Y13)=0,"",LEN(Y13)) | Z13: =IF(LEN(AA13)=0,"",LEN(AA13)) | AB13: =IF(LEN(AC13)=0,"",LEN(AC13)) | AD13: =IF(LEN(AE13)=0,"",LEN(AE13)) | AF13: =IF(LEN(AG13)=0,"",LEN(AG13)) | AH13: =IF(LEN(AI13)=0,"",LEN(AI13)) | AJ13: =IF(LEN(AK13)=0,"",LEN(AK13)) | AL13: =IF(LEN(AM13)=0,"",LEN(AM13)) | AN13: =IF(LEN(AO13)=0,"",LEN(AO13)) | AP13: =IF(LEN(AQ13)=0,"",LEN(AQ13)) | AR13: =IF(LEN(AS13)=0,"",LEN(AS13)) | AT13: =IF(LEN(AU13)=0,"",LEN(AU13)) | AV13: =IF(LEN(AW13)=0,"",LEN(AW13)) | AX13: =IF(LEN(AY13)=0,"",LEN(AY13)) | AZ13: =IF(LEN(BA13)=0,"",LEN(BA13)) | BB13: =IF(LEN(BC13)=0,"",LEN(BC13)) | BD13: =IF(LEN(BE13)=0,"",LEN(BE13)) | BF13: =IF(LEN(BG13)=0,"",LEN(BG13)) | BH13: =IF(LEN(BI13)=0,"",LEN(BI13)) | BJ13: =IF(LEN(BK13)=0,"",LEN(BK13)) | BL13: =IF(LEN(BM13)=0,"",LEN(BM13)) | BN13: =IF(LEN(BO13)=0,"",LEN(BO13)) | BP13: =IF(LEN(BQ13)=0,"",LEN(BQ13)) | BR13: =IF(LEN(BS13)=0,"",LEN(BS13)) | BT13: =IF(LEN(BU13)=0,"",LEN(BU13)) | BV13: =IF(LEN(BW13)=0,"",LEN(BW13)) | BX13: =IF(LEN(BY13)=0,"",LEN(BY13)) | BZ13: =IF(LEN(CA13)=0,"",LEN(CA13)) | CB13: =IF(LEN(CC13)=0,"",LEN(CC13)) | CD13: =IF(LEN(CE13)=0,"",LEN(CE13)) | CF13: =IF(LEN(CG13)=0,"",LEN(CG13)) | CH13: =IF(LEN(CI13)=0,"",LEN(CI13)) | CJ13: =IF(LEN(CK13)=0,"",LEN(CK13)) | CL13: =IF(LEN(CM13)=0,"",LEN(CM13)) | CN13: =IF(LEN(CO13)=0,"",LEN(CO13)) | CP13: =IF(LEN(CQ13)=0,"",LEN(CQ13)) | CR13: =IF(LEN(CS13)=0,"",LEN(CS13)) | CT13: =IF(LEN(CU13)=0,"",LEN(CU13)) | CV13: =IF(LEN(CW13)=0,"",LEN(CW13)) | CX13: =IF(LEN(CY13)=0,"",LEN(CY13)) | CZ13: =IF(LEN(DA13)=0,"",LEN(DA13)) | DB13: =IF(LEN(DC13)=0,"",LEN(DC13)) | DD13: =IF(LEN(DE13)=0,"",LEN(DE13)) | DF13: =IF(LEN(DG13)=0,"",LEN(DG13)) | DH13: =IF(LEN(DI13)=0,"",LEN(DI13)) | DJ13: =IF(LEN(DK13)=0,"",LEN(DK13)) | DL13: =IF(LEN(DM13)=0,"",LEN(DM13)) | DN13: =IF(LEN(DO13)=0,"",LEN(DO13)) | DP13: =IF(LEN(DQ13)=0,"",LEN(DQ13))
A14: Description 2 (90) | B14: =IF(LEN(C14)=0,"",LEN(C14)) -> 83 | C14: Fast, Reliable Emergency Plumbing Repairs. On-Site Rapidly To Prevent Water Damage. | D14: =IF(LEN(E14)=0,"",LEN(E14)) -> 89 | E14: Professional, Clean, And Respectful Residential Plumbing Services Tailored For Your Home. | F14: =IF(LEN(G14)=0,"",LEN(G14)) -> 89 | G14: We Support Property Managers, Retail Spaces & Office Blocks With Fast, Reliable Plumbing. | H14: =IF(LEN(I14)=0,"",LEN(I14)) -> 89 | I14: Advanced Acoustic And Thermal Leak Detection Technology To Pinpoint Water Loss Precisely. | J14: =IF(LEN(K14)=0,"",LEN(K14)) -> 80 | K14: Advanced Drain Cleaning, Camera Inspections, And High-Pressure Jetting Services. | L14: =IF(LEN(M14)=0,"",LEN(M14)) -> 85 | M14: Fast, Insurance-Approved Burst Geyser Replacements To Minimize Internal Water Damage. | N14: =IF(LEN(O14)=0,"",LEN(O14)) | P14: =IF(LEN(Q14)=0,"",LEN(Q14)) | R14: =IF(LEN(S14)=0,"",LEN(S14)) | T14: =IF(LEN(U14)=0,"",LEN(U14)) | V14: =IF(LEN(W14)=0,"",LEN(W14)) | X14: =IF(LEN(Y14)=0,"",LEN(Y14)) | Z14: =IF(LEN(AA14)=0,"",LEN(AA14)) | AB14: =IF(LEN(AC14)=0,"",LEN(AC14)) | AD14: =IF(LEN(AE14)=0,"",LEN(AE14)) | AF14: =IF(LEN(AG14)=0,"",LEN(AG14)) | AH14: =IF(LEN(AI14)=0,"",LEN(AI14)) | AJ14: =IF(LEN(AK14)=0,"",LEN(AK14)) | AL14: =IF(LEN(AM14)=0,"",LEN(AM14)) | AN14: =IF(LEN(AO14)=0,"",LEN(AO14)) | AP14: =IF(LEN(AQ14)=0,"",LEN(AQ14)) | AR14: =IF(LEN(AS14)=0,"",LEN(AS14)) | AT14: =IF(LEN(AU14)=0,"",LEN(AU14)) | AV14: =IF(LEN(AW14)=0,"",LEN(AW14)) | AX14: =IF(LEN(AY14)=0,"",LEN(AY14)) | AZ14: =IF(LEN(BA14)=0,"",LEN(BA14)) | BB14: =IF(LEN(BC14)=0,"",LEN(BC14)) | BD14: =IF(LEN(BE14)=0,"",LEN(BE14)) | BF14: =IF(LEN(BG14)=0,"",LEN(BG14)) | BH14: =IF(LEN(BI14)=0,"",LEN(BI14)) | BJ14: =IF(LEN(BK14)=0,"",LEN(BK14)) | BL14: =IF(LEN(BM14)=0,"",LEN(BM14)) | BN14: =IF(LEN(BO14)=0,"",LEN(BO14)) | BP14: =IF(LEN(BQ14)=0,"",LEN(BQ14)) | BR14: =IF(LEN(BS14)=0,"",LEN(BS14)) | BT14: =IF(LEN(BU14)=0,"",LEN(BU14)) | BV14: =IF(LEN(BW14)=0,"",LEN(BW14)) | BX14: =IF(LEN(BY14)=0,"",LEN(BY14)) | BZ14: =IF(LEN(CA14)=0,"",LEN(CA14)) | CB14: =IF(LEN(CC14)=0,"",LEN(CC14)) | CD14: =IF(LEN(CE14)=0,"",LEN(CE14)) | CF14: =IF(LEN(CG14)=0,"",LEN(CG14)) | CH14: =IF(LEN(CI14)=0,"",LEN(CI14)) | CJ14: =IF(LEN(CK14)=0,"",LEN(CK14)) | CL14: =IF(LEN(CM14)=0,"",LEN(CM14)) | CN14: =IF(LEN(CO14)=0,"",LEN(CO14)) | CP14: =IF(LEN(CQ14)=0,"",LEN(CQ14)) | CR14: =IF(LEN(CS14)=0,"",LEN(CS14)) | CT14: =IF(LEN(CU14)=0,"",LEN(CU14)) | CV14: =IF(LEN(CW14)=0,"",LEN(CW14)) | CX14: =IF(LEN(CY14)=0,"",LEN(CY14)) | CZ14: =IF(LEN(DA14)=0,"",LEN(DA14)) | DB14: =IF(LEN(DC14)=0,"",LEN(DC14)) | DD14: =IF(LEN(DE14)=0,"",LEN(DE14)) | DF14: =IF(LEN(DG14)=0,"",LEN(DG14)) | DH14: =IF(LEN(DI14)=0,"",LEN(DI14)) | DJ14: =IF(LEN(DK14)=0,"",LEN(DK14)) | DL14: =IF(LEN(DM14)=0,"",LEN(DM14)) | DN14: =IF(LEN(DO14)=0,"",LEN(DO14)) | DP14: =IF(LEN(DQ14)=0,"",LEN(DQ14))
... A16: Description 4 (90) | B16: =IF(LEN(C16)=0,"",LEN(C16)) -> 87 | C16: Highly Trained Emergency Technicians Equipped To Solve Any Plumbing Crisis Immediately. | D16: =IF(LEN(E16)=0,"",LEN(E16)) -> 90 | E16: Top-Rated Home Plumbing Repairs & Maintenance. Transparent Pricing And Quality Guaranteed. | F16: =IF(LEN(G16)=0,"",LEN(G16)) -> 88 | G16: Scheduled Maintenance Contracts And Emergency Corporate Repairs. Call Our Experts Today. | H16: =IF(LEN(I16)=0,"",LEN(I16)) -> 88 | I16: Professional Leak Tracing And Structural Damp Detection Services. Protect Your Property. | J16: =IF(LEN(K16)=0,"",LEN(K16)) -> 88 | K16: Reliable, Long-Lasting Drain Unblocking Solutions For Residential And Commercial Spaces. | L16: =IF(LEN(M16)=0,"",LEN(M16)) -> 89 | M16: Safe, Compliant Geyser Installations And Solar Conversions By Local Plumbing Specialists. | N16: =IF(LEN(O16)=0,"",LEN(O16)) | P16: =IF(LEN(Q16)=0,"",LEN(Q16)) | R16: =IF(LEN(S16)=0,"",LEN(S16)) | T16: =IF(LEN(U16)=0,"",LEN(U16)) | V16: =IF(LEN(W16)=0,"",LEN(W16)) | X16: =IF(LEN(Y16)=0,"",LEN(Y16)) | Z16: =IF(LEN(AA16)=0,"",LEN(AA16)) | AB16: =IF(LEN(AC16)=0,"",LEN(AC16)) | AD16: =IF(LEN(AE16)=0,"",LEN(AE16)) | AF16: =IF(LEN(AG16)=0,"",LEN(AG16)) | AH16: =IF(LEN(AI16)=0,"",LEN(AI16)) | AJ16: =IF(LEN(AK16)=0,"",LEN(AK16)) | AL16: =IF(LEN(AM16)=0,"",LEN(AM16)) | AN16: =IF(LEN(AO16)=0,"",LEN(AO16)) | AP16: =IF(LEN(AQ16)=0,"",LEN(AQ16)) | AR16: =IF(LEN(AS16)=0,"",LEN(AS16)) | AT16: =IF(LEN(AU16)=0,"",LEN(AU16)) | AV16: =IF(LEN(AW16)=0,"",LEN(AW16)) | AX16: =IF(LEN(AY16)=0,"",LEN(AY16)) | AZ16: =IF(LEN(BA16)=0,"",LEN(BA16)) | BB16: =IF(LEN(BC16)=0,"",LEN(BC16)) | BD16: =IF(LEN(BE16)=0,"",LEN(BE16)) | BF16: =IF(LEN(BG16)=0,"",LEN(BG16)) | BH16: =IF(LEN(BI16)=0,"",LEN(BI16)) | BJ16: =IF(LEN(BK16)=0,"",LEN(BK16)) | BL16: =IF(LEN(BM16)=0,"",LEN(BM16)) | BN16: =IF(LEN(BO16)=0,"",LEN(BO16)) | BP16: =IF(LEN(BQ16)=0,"",LEN(BQ16)) | BR16: =IF(LEN(BS16)=0,"",LEN(BS16)) | BT16: =IF(LEN(BU16)=0,"",LEN(BU16)) | BV16: =IF(LEN(BW16)=0,"",LEN(BW16)) | BX16: =IF(LEN(BY16)=0,"",LEN(BY16)) | BZ16: =IF(LEN(CA16)=0,"",LEN(CA16)) | CB16: =IF(LEN(CC16)=0,"",LEN(CC16)) | CD16: =IF(LEN(CE16)=0,"",LEN(CE16)) | CF16: =IF(LEN(CG16)=0,"",LEN(CG16)) | CH16: =IF(LEN(CI16)=0,"",LEN(CI16)) | CJ16: =IF(LEN(CK16)=0,"",LEN(CK16)) | CL16: =IF(LEN(CM16)=0,"",LEN(CM16)) | CN16: =IF(LEN(CO16)=0,"",LEN(CO16)) | CP16: =IF(LEN(CQ16)=0,"",LEN(CQ16)) | CR16: =IF(LEN(CS16)=0,"",LEN(CS16)) | CT16: =IF(LEN(CU16)=0,"",LEN(CU16)) | CV16: =IF(LEN(CW16)=0,"",LEN(CW16)) | CX16: =IF(LEN(CY16)=0,"",LEN(CY16)) | CZ16: =IF(LEN(DA16)=0,"",LEN(DA16)) | DB16: =IF(LEN(DC16)=0,"",LEN(DC16)) | DD16: =IF(LEN(DE16)=0,"",LEN(DE16)) | DF16: =IF(LEN(DG16)=0,"",LEN(DG16)) | DH16: =IF(LEN(DI16)=0,"",LEN(DI16)) | DJ16: =IF(LEN(DK16)=0,"",LEN(DK16)) | DL16: =IF(LEN(DM16)=0,"",LEN(DM16)) | DN16: =IF(LEN(DO16)=0,"",LEN(DO16)) | DP16: =IF(LEN(DQ16)=0,"",LEN(DQ16))
A17: Display URL | B17: =IF(LEN(C17)=0,"",LEN(C17)) -> 46 | C17: https://angelplumbers.co.za/Emergency_Plumbing | E17: https://angelplumbers.co.za/Residential-Plumbing | G17: https://angelplumbers.co.za/Commercial_Plumbing | I17: https://angelplumbers.co.za/Leak-Detection | K17: https://angelplumbers.co.za/Drain_Cleaning | M17: https://angelplumbers.co.za/Geyser_Replacement_&_Repairs | N17: =IF(LEN(O17)=0,"",LEN(O17)) | P17: =IF(LEN(Q17)=0,"",LEN(Q17)) | R17: =IF(LEN(S17)=0,"",LEN(S17)) | T17: =IF(LEN(U17)=0,"",LEN(U17)) | V17: =IF(LEN(W17)=0,"",LEN(W17)) | X17: =IF(LEN(Y17)=0,"",LEN(Y17)) | Z17: =IF(LEN(AA17)=0,"",LEN(AA17)) | AB17: =IF(LEN(AC17)=0,"",LEN(AC17)) | AD17: =IF(LEN(AE17)=0,"",LEN(AE17)) | AF17: =IF(LEN(AG17)=0,"",LEN(AG17)) | AH17: =IF(LEN(AI17)=0,"",LEN(AI17)) | AJ17: =IF(LEN(AK17)=0,"",LEN(AK17)) | AL17: =IF(LEN(AM17)=0,"",LEN(AM17)) | AN17: =IF(LEN(AO17)=0,"",LEN(AO17)) | AP17: =IF(LEN(AQ17)=0,"",LEN(AQ17)) | AR17: =IF(LEN(AS17)=0,"",LEN(AS17)) | AT17: =IF(LEN(AU17)=0,"",LEN(AU17)) | AV17: =IF(LEN(AW17)=0,"",LEN(AW17)) | AX17: =IF(LEN(AY17)=0,"",LEN(AY17)) | AZ17: =IF(LEN(BA17)=0,"",LEN(BA17)) | BB17: =IF(LEN(BC17)=0,"",LEN(BC17)) | BD17: =IF(LEN(BE17)=0,"",LEN(BE17)) | BF17: =IF(LEN(BG17)=0,"",LEN(BG17)) | BH17: =IF(LEN(BI17)=0,"",LEN(BI17)) | BJ17: =IF(LEN(BK17)=0,"",LEN(BK17)) | BL17: =IF(LEN(BM17)=0,"",LEN(BM17)) | BN17: =IF(LEN(BO17)=0,"",LEN(BO17)) | BP17: =IF(LEN(BQ17)=0,"",LEN(BQ17)) | BR17: =IF(LEN(BS17)=0,"",LEN(BS17)) | BT17: =IF(LEN(BU17)=0,"",LEN(BU17)) | BV17: =IF(LEN(BW17)=0,"",LEN(BW17)) | BX17: =IF(LEN(BY17)=0,"",LEN(BY17)) | BZ17: =IF(LEN(CA17)=0,"",LEN(CA17)) | CB17: =IF(LEN(CC17)=0,"",LEN(CC17)) | CD17: =IF(LEN(CE17)=0,"",LEN(CE17)) | CF17: =IF(LEN(CG17)=0,"",LEN(CG17)) | CH17: =IF(LEN(CI17)=0,"",LEN(CI17)) | CJ17: =IF(LEN(CK17)=0,"",LEN(CK17)) | CL17: =IF(LEN(CM17)=0,"",LEN(CM17)) | CN17: =IF(LEN(CO17)=0,"",LEN(CO17)) | CP17: =IF(LEN(CQ17)=0,"",LEN(CQ17)) | CR17: =IF(LEN(CS17)=0,"",LEN(CS17)) | CT17: =IF(LEN(CU17)=0,"",LEN(CU17)) | CV17: =IF(LEN(CW17)=0,"",LEN(CW17)) | CX17: =IF(LEN(CY17)=0,"",LEN(CY17)) | CZ17: =IF(LEN(DA17)=0,"",LEN(DA17)) | DB17: =IF(LEN(DC17)=0,"",LEN(DC17)) | DD17: =IF(LEN(DE17)=0,"",LEN(DE17)) | DF17: =IF(LEN(DG17)=0,"",LEN(DG17)) | DH17: =IF(LEN(DI17)=0,"",LEN(DI17)) | DJ17: =IF(LEN(DK17)=0,"",LEN(DK17)) | DL17: =IF(LEN(DM17)=0,"",LEN(DM17)) | DN17: =IF(LEN(DO17)=0,"",LEN(DO17)) | DP17: =IF(LEN(DQ17)=0,"",LEN(DQ17))
A18: Final URL | B18: =IF(LEN(C18)=0,"",LEN(C18)) -> 28 | C18: https://angelplumbers.co.za/ | E18: https://angelplumbers.co.za/ | G18: https://angelplumbers.co.za/ | I18: https://angelplumbers.co.za/ | K18: https://angelplumbers.co.za/ | M18: https://angelplumbers.co.za/ | N18: =IF(LEN(O18)=0,"",LEN(O18)) | P18: =IF(LEN(Q18)=0,"",LEN(Q18)) | R18: =IF(LEN(S18)=0,"",LEN(S18)) | T18: =IF(LEN(U18)=0,"",LEN(U18)) | V18: =IF(LEN(W18)=0,"",LEN(W18)) | X18: =IF(LEN(Y18)=0,"",LEN(Y18)) | Z18: =IF(LEN(AA18)=0,"",LEN(AA18)) | AB18: =IF(LEN(AC18)=0,"",LEN(AC18)) | AD18: =IF(LEN(AE18)=0,"",LEN(AE18)) | AF18: =IF(LEN(AG18)=0,"",LEN(AG18)) | AH18: =IF(LEN(AI18)=0,"",LEN(AI18)) | AJ18: =IF(LEN(AK18)=0,"",LEN(AK18)) | AL18: =IF(LEN(AM18)=0,"",LEN(AM18)) | AN18: =IF(LEN(AO18)=0,"",LEN(AO18)) | AP18: =IF(LEN(AQ18)=0,"",LEN(AQ18)) | AR18: =IF(LEN(AS18)=0,"",LEN(AS18)) | AT18: =IF(LEN(AU18)=0,"",LEN(AU18)) | AV18: =IF(LEN(AW18)=0,"",LEN(AW18)) | AX18: =IF(LEN(AY18)=0,"",LEN(AY18)) | AZ18: =IF(LEN(BA18)=0,"",LEN(BA18)) | BB18: =IF(LEN(BC18)=0,"",LEN(BC18)) | BD18: =IF(LEN(BE18)=0,"",LEN(BE18)) | BF18: =IF(LEN(BG18)=0,"",LEN(BG18)) | BH18: =IF(LEN(BI18)=0,"",LEN(BI18)) | BJ18: =IF(LEN(BK18)=0,"",LEN(BK18)) | BL18: =IF(LEN(BM18)=0,"",LEN(BM18)) | BN18: =IF(LEN(BO18)=0,"",LEN(BO18)) | BP18: =IF(LEN(BQ18)=0,"",LEN(BQ18)) | BR18: =IF(LEN(BS18)=0,"",LEN(BS18)) | BT18: =IF(LEN(BU18)=0,"",LEN(BU18)) | BV18: =IF(LEN(BW18)=0,"",LEN(BW18)) | BX18: =IF(LEN(BY18)=0,"",LEN(BY18)) | BZ18: =IF(LEN(CA18)=0,"",LEN(CA18)) | CB18: =IF(LEN(CC18)=0,"",LEN(CC18)) | CD18: =IF(LEN(CE18)=0,"",LEN(CE18)) | CF18: =IF(LEN(CG18)=0,"",LEN(CG18)) | CH18: =IF(LEN(CI18)=0,"",LEN(CI18)) | CJ18: =IF(LEN(CK18)=0,"",LEN(CK18)) | CL18: =IF(LEN(CM18)=0,"",LEN(CM18)) | CN18: =IF(LEN(CO18)=0,"",LEN(CO18)) | CP18: =IF(LEN(CQ18)=0,"",LEN(CQ18)) | CR18: =IF(LEN(CS18)=0,"",LEN(CS18)) | CT18: =IF(LEN(CU18)=0,"",LEN(CU18)) | CV18: =IF(LEN(CW18)=0,"",LEN(CW18)) | CX18: =IF(LEN(CY18)=0,"",LEN(CY18)) | CZ18: =IF(LEN(DA18)=0,"",LEN(DA18)) | DB18: =IF(LEN(DC18)=0,"",LEN(DC18)) | DD18: =IF(LEN(DE18)=0,"",LEN(DE18)) | DF18: =IF(LEN(DG18)=0,"",LEN(DG18)) | DH18: =IF(LEN(DI18)=0,"",LEN(DI18)) | DJ18: =IF(LEN(DK18)=0,"",LEN(DK18)) | DL18: =IF(LEN(DM18)=0,"",LEN(DM18)) | DN18: =IF(LEN(DO18)=0,"",LEN(DO18)) | DP18: =IF(LEN(DQ18)=0,"",LEN(DQ18))
B19: =IF(LEN(C19)=0,"",LEN(C19))
A21: Headline 1 (30) | B21: =IF(LEN(C21)=0,"",LEN(C21)) -> 23 | C21: Local Emergency Plumber | D21: =IF(LEN(E21)=0,"",LEN(E21)) -> 27 | E21: Your Trusted Family Plumber | F21: =IF(LEN(G21)=0,"",LEN(G21)) -> 28 | G21: Certified Corporate Plumbers | H21: =IF(LEN(I21)=0,"",LEN(I21)) -> 24 | I21: Certified Leak Detectors | J21: =IF(LEN(K21)=0,"",LEN(K21)) -> 24 | K21: Sewer Camera Inspections | L21: =IF(LEN(M21)=0,"",LEN(M21)) -> 27 | M21: PIRB Compliant Geyser Swaps | N21: =IF(LEN(O21)=0,"",LEN(O21)) | P21: =IF(LEN(Q21)=0,"",LEN(Q21)) | R21: =IF(LEN(S21)=0,"",LEN(S21)) | T21: =IF(LEN(U21)=0,"",LEN(U21)) | V21: =IF(LEN(W21)=0,"",LEN(W21)) | X21: =IF(LEN(Y21)=0,"",LEN(Y21)) | Z21: =IF(LEN(AA21)=0,"",LEN(AA21)) | AB21: =IF(LEN(AC21)=0,"",LEN(AC21)) | AD21: =IF(LEN(AE21)=0,"",LEN(AE21)) | AF21: =IF(LEN(AG21)=0,"",LEN(AG21)) | AH21: =IF(LEN(AI21)=0,"",LEN(AI21)) | AJ21: =IF(LEN(AK21)=0,"",LEN(AK21)) | AL21: =IF(LEN(AM21)=0,"",LEN(AM21)) | AN21: =IF(LEN(AO21)=0,"",LEN(AO21)) | AP21: =IF(LEN(AQ21)=0,"",LEN(AQ21)) | AR21: =IF(LEN(AS21)=0,"",LEN(AS21)) | AT21: =IF(LEN(AU21)=0,"",LEN(AU21)) | AV21: =IF(LEN(AW21)=0,"",LEN(AW21)) | AX21: =IF(LEN(AY21)=0,"",LEN(AY21)) | AZ21: =IF(LEN(BA21)=0,"",LEN(BA21)) | BB21: =IF(LEN(BC21)=0,"",LEN(BC21)) | BD21: =IF(LEN(BE21)=0,"",LEN(BE21)) | BF21: =IF(LEN(BG21)=0,"",LEN(BG21)) | BH21: =IF(LEN(BI21)=0,"",LEN(BI21)) | BJ21: =IF(LEN(BK21)=0,"",LEN(BK21)) | BL21: =IF(LEN(BM21)=0,"",LEN(BM21)) | BN21: =IF(LEN(BO21)=0,"",LEN(BO21)) | BP21: =IF(LEN(BQ21)=0,"",LEN(BQ21)) | BR21: =IF(LEN(BS21)=0,"",LEN(BS21)) | BT21: =IF(LEN(BU21)=0,"",LEN(BU21)) | BV21: =IF(LEN(BW21)=0,"",LEN(BW21)) | BX21: =IF(LEN(BY21)=0,"",LEN(BY21)) | BZ21: =IF(LEN(CA21)=0,"",LEN(CA21)) | CB21: =IF(LEN(CC21)=0,"",LEN(CC21)) | CD21: =IF(LEN(CE21)=0,"",LEN(CE21)) | CF21: =IF(LEN(CG21)=0,"",LEN(CG21)) | CH21: =IF(LEN(CI21)=0,"",LEN(CI21)) | CJ21: =IF(LEN(CK21)=0,"",LEN(CK21)) | CL21: =IF(LEN(CM21)=0,"",LEN(CM21)) | CN21: =IF(LEN(CO21)=0,"",LEN(CO21)) | CP21: =IF(LEN(CQ21)=0,"",LEN(CQ21)) | CR21: =IF(LEN(CS21)=0,"",LEN(CS21)) | CT21: =IF(LEN(CU21)=0,"",LEN(CU21)) | CV21: =IF(LEN(CW21)=0,"",LEN(CW21)) | CX21: =IF(LEN(CY21)=0,"",LEN(CY21)) | CZ21: =IF(LEN(DA21)=0,"",LEN(DA21)) | DB21: =IF(LEN(DC21)=0,"",LEN(DC21)) | DD21: =IF(LEN(DE21)=0,"",LEN(DE21)) | DF21: =IF(LEN(DG21)=0,"",LEN(DG21)) | DH21: =IF(LEN(DI21)=0,"",LEN(DI21)) | DJ21: =IF(LEN(DK21)=0,"",LEN(DK21)) | DL21: =IF(LEN(DM21)=0,"",LEN(DM21)) | DN21: =IF(LEN(DO21)=0,"",LEN(DO21)) | DP21: =IF(LEN(DQ21)=0,"",LEN(DQ21))
A22: Headline 2 (30) | B22: =IF(LEN(C22)=0,"",LEN(C22)) -> 24 | C22: No Hidden Emergency Fees | D22: =IF(LEN(E22)=0,"",LEN(E22)) -> 28 | E22: Upfront Fixed Pricing Quotes | F22: =IF(LEN(G22)=0,"",LEN(G22)) -> 25 | G22: Property Manager Plumbing | H22: =IF(LEN(I22)=0,"",LEN(I22)) -> 25 | I22: Save Money On Water Bills | J22: =IF(LEN(K22)=0,"",LEN(K22)) -> 28 | K22: High Pressure Jet Unblocking | L22: =IF(LEN(M22)=0,"",LEN(M22)) -> 28 | M22: Certified Water Heater Techs | N22: =IF(LEN(O22)=0,"",LEN(O22)) | P22: =IF(LEN(Q22)=0,"",LEN(Q22)) | R22: =IF(LEN(S22)=0,"",LEN(S22)) | T22: =IF(LEN(U22)=0,"",LEN(U22)) | V22: =IF(LEN(W22)=0,"",LEN(W22)) | X22: =IF(LEN(Y22)=0,"",LEN(Y22)) | Z22: =IF(LEN(AA22)=0,"",LEN(AA22)) | AB22: =IF(LEN(AC22)=0,"",LEN(AC22)) | AD22: =IF(LEN(AE22)=0,"",LEN(AE22)) | AF22: =IF(LEN(AG22)=0,"",LEN(AG22)) | AH22: =IF(LEN(AI22)=0,"",LEN(AI22)) | AJ22: =IF(LEN(AK22)=0,"",LEN(AK22)) | AL22: =IF(LEN(AM22)=0,"",LEN(AM22)) | AN22: =IF(LEN(AO22)=0,"",LEN(AO22)) | AP22: =IF(LEN(AQ22)=0,"",LEN(AQ22)) | AR22: =IF(LEN(AS22)=0,"",LEN(AS22)) | AT22: =IF(LEN(AU22)=0,"",LEN(AU22)) | AV22: =IF(LEN(AW22)=0,"",LEN(AW22)) | AX22: =IF(LEN(AY22)=0,"",LEN(AY22)) | AZ22: =IF(LEN(BA22)=0,"",LEN(BA22)) | BB22: =IF(LEN(BC22)=0,"",LEN(BC22)) | BD22: =IF(LEN(BE22)=0,"",LEN(BE22)) | BF22: =IF(LEN(BG22)=0,"",LEN(BG22)) | BH22: =IF(LEN(BI22)=0,"",LEN(BI22)) | BJ22: =IF(LEN(BK22)=0,"",LEN(BK22)) | BL22: =IF(LEN(BM22)=0,"",LEN(BM22)) | BN22: =IF(LEN(BO22)=0,"",LEN(BO22)) | BP22: =IF(LEN(BQ22)=0,"",LEN(BQ22)) | BR22: =IF(LEN(BS22)=0,"",LEN(BS22)) | BT22: =IF(LEN(BU22)=0,"",LEN(BU22)) | BV22: =IF(LEN(BW22)=0,"",LEN(BW22)) | BX22: =IF(LEN(BY22)=0,"",LEN(BY22)) | BZ22: =IF(LEN(CA22)=0,"",LEN(CA22)) | CB22: =IF(LEN(CC22)=0,"",LEN(CC22)) | CD22: =IF(LEN(CE22)=0,"",LEN(CE22)) | CF22: =IF(LEN(CG22)=0,"",LEN(CG22)) | CH22: =IF(LEN(CI22)=0,"",LEN(CI22)) | CJ22: =IF(LEN(CK22)=0,"",LEN(CK22)) | CL22: =IF(LEN(CM22)=0,"",LEN(CM22)) | CN22: =IF(LEN(CO22)=0,"",LEN(CO22)) | CP22: =IF(LEN(CQ22)=0,"",LEN(CQ22)) | CR22: =IF(LEN(CS22)=0,"",LEN(CS22)) | CT22: =IF(LEN(CU22)=0,"",LEN(CU22)) | CV22: =IF(LEN(CW22)=0,"",LEN(CW22)) | CX22: =IF(LEN(CY22)=0,"",LEN(CY22)) | CZ22: =IF(LEN(DA22)=0,"",LEN(DA22)) | DB22: =IF(LEN(DC22)=0,"",LEN(DC22)) | DD22: =IF(LEN(DE22)=0,"",LEN(DE22)) | DF22: =IF(LEN(DG22)=0,"",LEN(DG22)) | DH22: =IF(LEN(DI22)=0,"",LEN(DI22)) | DJ22: =IF(LEN(DK22)=0,"",LEN(DK22)) | DL22: =IF(LEN(DM22)=0,"",LEN(DM22)) | DN22: =IF(LEN(DO22)=0,"",LEN(DO22)) | DP22: =IF(LEN(DQ22)=0,"",LEN(DQ22))
